WARNING:django.request:Not Found: /favicon.ico
DEBUG:root:prudhvi
DEBUG:root:k.prudhvireddy1996@gmail.com
DEBUG:asyncio:Using proactor: IocpProactor
DEBUG:asyncio:Using proactor: IocpProactor
DEBUG:asyncio:Using proactor: IocpProactor
WARNING:django.request:Not Found: /favicon.ico
WARNING:django.request:Not Found: /blogs
DEBUG:root:prudhvi
DEBUG:root:k.prudhvireddy1996@gmail.com
DEBUG:asyncio:Using proactor: IocpProactor
DEBUG:root:prudhvi
DEBUG:root:k.prudhvireddy1996@gmail.com
DEBUG:asyncio:Using proactor: IocpProactor
DEBUG:asyncio:Using proactor: IocpProactor
DEBUG:PIL.Image:Importing BlpImagePlugin
DEBUG:PIL.Image:Importing BmpImagePlugin
DEBUG:PIL.Image:Importing BufrStubImagePlugin
DEBUG:PIL.Image:Importing CurImagePlugin
DEBUG:PIL.Image:Importing DcxImagePlugin
DEBUG:PIL.Image:Importing DdsImagePlugin
DEBUG:PIL.Image:Importing EpsImagePlugin
DEBUG:PIL.Image:Importing FitsStubImagePlugin
DEBUG:PIL.Image:Importing FliImagePlugin
DEBUG:PIL.Image:Importing FpxImagePlugin
DEBUG:PIL.Image:Importing FtexImagePlugin
DEBUG:PIL.Image:Importing GbrImagePlugin
DEBUG:PIL.Image:Importing GifImagePlugin
DEBUG:PIL.Image:Importing GribStubImagePlugin
DEBUG:PIL.Image:Importing Hdf5StubImagePlugin
DEBUG:PIL.Image:Importing IcnsImagePlugin
DEBUG:PIL.Image:Importing IcoImagePlugin
DEBUG:PIL.Image:Importing ImImagePlugin
DEBUG:PIL.Image:Importing ImtImagePlugin
DEBUG:PIL.Image:Importing IptcImagePlugin
DEBUG:PIL.Image:Importing JpegImagePlugin
DEBUG:PIL.Image:Importing Jpeg2KImagePlugin
DEBUG:PIL.Image:Importing McIdasImagePlugin
DEBUG:PIL.Image:Importing MicImagePlugin
DEBUG:PIL.Image:Importing MpegImagePlugin
DEBUG:PIL.Image:Importing MpoImagePlugin
DEBUG:PIL.Image:Importing MspImagePlugin
DEBUG:PIL.Image:Importing PalmImagePlugin
DEBUG:PIL.Image:Importing PcdImagePlugin
DEBUG:PIL.Image:Importing PcxImagePlugin
DEBUG:PIL.Image:Importing PdfImagePlugin
DEBUG:PIL.Image:Importing PixarImagePlugin
DEBUG:PIL.Image:Importing PngImagePlugin
DEBUG:PIL.Image:Importing PpmImagePlugin
DEBUG:PIL.Image:Importing PsdImagePlugin
DEBUG:PIL.Image:Importing SgiImagePlugin
DEBUG:PIL.Image:Importing SpiderImagePlugin
DEBUG:PIL.Image:Importing SunImagePlugin
DEBUG:PIL.Image:Importing TgaImagePlugin
DEBUG:PIL.Image:Importing TiffImagePlugin
DEBUG:PIL.Image:Importing WebPImagePlugin
DEBUG:PIL.Image:Importing WmfImagePlugin
DEBUG:PIL.Image:Importing XbmImagePlugin
DEBUG:PIL.Image:Importing XpmImagePlugin
DEBUG:PIL.Image:Importing XVThumbImagePlugin
INFO:django.utils.autoreload:C:\Users\kprud\PycharmProjects\Project\blog\views.py changed, reloading.
DEBUG:asyncio:Using proactor: IocpProactor
INFO:django.utils.autoreload:C:\Users\kprud\PycharmProjects\Project\blog\views.py changed, reloading.
DEBUG:asyncio:Using proactor: IocpProactor
DEBUG:PIL.TiffImagePlugin:tag: Orientation (274) - type: short (3) - value: b'\x00\x01'
DEBUG:PIL.TiffImagePlugin:tag: XResolution (282) - type: rational (5) Tag Location: 34 - Data Location: 98 - value: b"\x00\n\xfc\x80\x00\x00'\x10"
DEBUG:PIL.TiffImagePlugin:tag: YResolution (283) - type: rational (5) Tag Location: 46 - Data Location: 106 - value: b"\x00\n\xfc\x80\x00\x00'\x10"
DEBUG:PIL.TiffImagePlugin:tag: ResolutionUnit (296) - type: short (3) - value: b'\x00\x02'
DEBUG:PIL.TiffImagePlugin:tag: Software (305) - type: string (2) Tag Location: 70 - Data Location: 114 - value: <table: 33 bytes>
DEBUG:PIL.TiffImagePlugin:tag: DateTime (306) - type: string (2) Tag Location: 82 - Data Location: 147 - value: b'2020:10:04 23:38:23\x00'
DEBUG:PIL.TiffImagePlugin:tag: ExifIFD (34665) - type: long (4) - value: b'\x00\x00\x00\xa8'
DEBUG:PIL.Image:Importing BlpImagePlugin
DEBUG:PIL.Image:Importing BmpImagePlugin
DEBUG:PIL.Image:Importing BufrStubImagePlugin
DEBUG:PIL.Image:Importing CurImagePlugin
DEBUG:PIL.Image:Importing DcxImagePlugin
DEBUG:PIL.Image:Importing DdsImagePlugin
DEBUG:PIL.Image:Importing EpsImagePlugin
DEBUG:PIL.Image:Importing FitsStubImagePlugin
DEBUG:PIL.Image:Importing FliImagePlugin
DEBUG:PIL.Image:Importing FpxImagePlugin
DEBUG:PIL.Image:Importing FtexImagePlugin
DEBUG:PIL.Image:Importing GbrImagePlugin
DEBUG:PIL.Image:Importing GifImagePlugin
DEBUG:PIL.Image:Importing GribStubImagePlugin
DEBUG:PIL.Image:Importing Hdf5StubImagePlugin
DEBUG:PIL.Image:Importing IcnsImagePlugin
DEBUG:PIL.Image:Importing IcoImagePlugin
DEBUG:PIL.Image:Importing ImImagePlugin
DEBUG:PIL.Image:Importing ImtImagePlugin
DEBUG:PIL.Image:Importing IptcImagePlugin
DEBUG:PIL.Image:Importing JpegImagePlugin
DEBUG:PIL.Image:Importing Jpeg2KImagePlugin
DEBUG:PIL.Image:Importing McIdasImagePlugin
DEBUG:PIL.Image:Importing MicImagePlugin
DEBUG:PIL.Image:Importing MpegImagePlugin
DEBUG:PIL.Image:Importing MpoImagePlugin
DEBUG:PIL.Image:Importing MspImagePlugin
DEBUG:PIL.Image:Importing PalmImagePlugin
DEBUG:PIL.Image:Importing PcdImagePlugin
DEBUG:PIL.Image:Importing PcxImagePlugin
DEBUG:PIL.Image:Importing PdfImagePlugin
DEBUG:PIL.Image:Importing PixarImagePlugin
DEBUG:PIL.Image:Importing PngImagePlugin
DEBUG:PIL.Image:Importing PpmImagePlugin
DEBUG:PIL.Image:Importing PsdImagePlugin
DEBUG:PIL.Image:Importing SgiImagePlugin
DEBUG:PIL.Image:Importing SpiderImagePlugin
DEBUG:PIL.Image:Importing SunImagePlugin
DEBUG:PIL.Image:Importing TgaImagePlugin
DEBUG:PIL.Image:Importing TiffImagePlugin
DEBUG:PIL.Image:Importing WebPImagePlugin
DEBUG:PIL.Image:Importing WmfImagePlugin
DEBUG:PIL.Image:Importing XbmImagePlugin
DEBUG:PIL.Image:Importing XpmImagePlugin
DEBUG:PIL.Image:Importing XVThumbImagePlugin
DEBUG:PIL.TiffImagePlugin:tag: Orientation (274) - type: short (3) - value: b'\x00\x01'
DEBUG:PIL.TiffImagePlugin:tag: XResolution (282) - type: rational (5) Tag Location: 34 - Data Location: 98 - value: b"\x00\n\xfc\x80\x00\x00'\x10"
DEBUG:PIL.TiffImagePlugin:tag: YResolution (283) - type: rational (5) Tag Location: 46 - Data Location: 106 - value: b"\x00\n\xfc\x80\x00\x00'\x10"
DEBUG:PIL.TiffImagePlugin:tag: ResolutionUnit (296) - type: short (3) - value: b'\x00\x02'
DEBUG:PIL.TiffImagePlugin:tag: Software (305) - type: string (2) Tag Location: 70 - Data Location: 114 - value: <table: 33 bytes>
DEBUG:PIL.TiffImagePlugin:tag: DateTime (306) - type: string (2) Tag Location: 82 - Data Location: 147 - value: b'2020:10:04 23:38:23\x00'
DEBUG:PIL.TiffImagePlugin:tag: ExifIFD (34665) - type: long (4) - value: b'\x00\x00\x00\xa8'
INFO:django.utils.autoreload:C:\Users\kprud\PycharmProjects\Project\blog\views.py changed, reloading.
DEBUG:asyncio:Using proactor: IocpProactor
INFO:django.utils.autoreload:C:\Users\kprud\PycharmProjects\Project\blog\models.py changed, reloading.
DEBUG:asyncio:Using proactor: IocpProactor
DEBUG:asyncio:Using proactor: IocpProactor
DEBUG:asyncio:Using proactor: IocpProactor
DEBUG:PIL.Image:Importing BlpImagePlugin
DEBUG:PIL.Image:Importing BmpImagePlugin
DEBUG:PIL.Image:Importing BufrStubImagePlugin
DEBUG:PIL.Image:Importing CurImagePlugin
DEBUG:PIL.Image:Importing DcxImagePlugin
DEBUG:PIL.Image:Importing DdsImagePlugin
DEBUG:PIL.Image:Importing EpsImagePlugin
DEBUG:PIL.Image:Importing FitsStubImagePlugin
DEBUG:PIL.Image:Importing FliImagePlugin
DEBUG:PIL.Image:Importing FpxImagePlugin
DEBUG:PIL.Image:Importing FtexImagePlugin
DEBUG:PIL.Image:Importing GbrImagePlugin
DEBUG:PIL.Image:Importing GifImagePlugin
DEBUG:PIL.Image:Importing GribStubImagePlugin
DEBUG:PIL.Image:Importing Hdf5StubImagePlugin
DEBUG:PIL.Image:Importing IcnsImagePlugin
DEBUG:PIL.Image:Importing IcoImagePlugin
DEBUG:PIL.Image:Importing ImImagePlugin
DEBUG:PIL.Image:Importing ImtImagePlugin
DEBUG:PIL.Image:Importing IptcImagePlugin
DEBUG:PIL.Image:Importing JpegImagePlugin
DEBUG:PIL.Image:Importing Jpeg2KImagePlugin
DEBUG:PIL.Image:Importing McIdasImagePlugin
DEBUG:PIL.Image:Importing MicImagePlugin
DEBUG:PIL.Image:Importing MpegImagePlugin
DEBUG:PIL.Image:Importing MpoImagePlugin
DEBUG:PIL.Image:Importing MspImagePlugin
DEBUG:PIL.Image:Importing PalmImagePlugin
DEBUG:PIL.Image:Importing PcdImagePlugin
DEBUG:PIL.Image:Importing PcxImagePlugin
DEBUG:PIL.Image:Importing PdfImagePlugin
DEBUG:PIL.Image:Importing PixarImagePlugin
DEBUG:PIL.Image:Importing PngImagePlugin
DEBUG:PIL.Image:Importing PpmImagePlugin
DEBUG:PIL.Image:Importing PsdImagePlugin
DEBUG:PIL.Image:Importing SgiImagePlugin
DEBUG:PIL.Image:Importing SpiderImagePlugin
DEBUG:PIL.Image:Importing SunImagePlugin
DEBUG:PIL.Image:Importing TgaImagePlugin
DEBUG:PIL.Image:Importing TiffImagePlugin
DEBUG:PIL.Image:Importing WebPImagePlugin
DEBUG:PIL.Image:Importing WmfImagePlugin
DEBUG:PIL.Image:Importing XbmImagePlugin
DEBUG:PIL.Image:Importing XpmImagePlugin
DEBUG:PIL.Image:Importing XVThumbImagePlugin
DEBUG:urllib3.connectionpool:Starting new HTTP connection (1): api.open-notify.org:80
DEBUG:urllib3.connectionpool:http://api.open-notify.org:80 "GET /astros.json HTTP/1.1" 200 497
DEBUG:root:prudhvi
DEBUG:root:k.prudhvireddy1996@gmail.com
INFO:django.utils.autoreload:C:\Users\kprud\PycharmProjects\Project\blog\models.py changed, reloading.
DEBUG:asyncio:Using proactor: IocpProactor
INFO:django.utils.autoreload:C:\Users\kprud\PycharmProjects\Project\blog\views.py changed, reloading.
DEBUG:asyncio:Using proactor: IocpProactor
INFO:django.utils.autoreload:C:\Users\kprud\PycharmProjects\Project\blog\views.py changed, reloading.
DEBUG:asyncio:Using proactor: IocpProactor
DEBUG:asyncio:Using proactor: IocpProactor
DEBUG:PIL.TiffImagePlugin:tag: Orientation (274) - type: short (3) - value: b'\x00\x01'
DEBUG:PIL.TiffImagePlugin:tag: XResolution (282) - type: rational (5) Tag Location: 34 - Data Location: 98 - value: b"\x00\n\xfc\x80\x00\x00'\x10"
DEBUG:PIL.TiffImagePlugin:tag: YResolution (283) - type: rational (5) Tag Location: 46 - Data Location: 106 - value: b"\x00\n\xfc\x80\x00\x00'\x10"
DEBUG:PIL.TiffImagePlugin:tag: ResolutionUnit (296) - type: short (3) - value: b'\x00\x02'
DEBUG:PIL.TiffImagePlugin:tag: Software (305) - type: string (2) Tag Location: 70 - Data Location: 114 - value: <table: 33 bytes>
DEBUG:PIL.TiffImagePlugin:tag: DateTime (306) - type: string (2) Tag Location: 82 - Data Location: 147 - value: b'2020:10:04 23:38:23\x00'
DEBUG:PIL.TiffImagePlugin:tag: ExifIFD (34665) - type: long (4) - value: b'\x00\x00\x00\xa8'
DEBUG:PIL.Image:Importing BlpImagePlugin
DEBUG:PIL.Image:Importing BmpImagePlugin
DEBUG:PIL.Image:Importing BufrStubImagePlugin
DEBUG:PIL.Image:Importing CurImagePlugin
DEBUG:PIL.Image:Importing DcxImagePlugin
DEBUG:PIL.Image:Importing DdsImagePlugin
DEBUG:PIL.Image:Importing EpsImagePlugin
DEBUG:PIL.Image:Importing FitsStubImagePlugin
DEBUG:PIL.Image:Importing FliImagePlugin
DEBUG:PIL.Image:Importing FpxImagePlugin
DEBUG:PIL.Image:Importing FtexImagePlugin
DEBUG:PIL.Image:Importing GbrImagePlugin
DEBUG:PIL.Image:Importing GifImagePlugin
DEBUG:PIL.Image:Importing GribStubImagePlugin
DEBUG:PIL.Image:Importing Hdf5StubImagePlugin
DEBUG:PIL.Image:Importing IcnsImagePlugin
DEBUG:PIL.Image:Importing IcoImagePlugin
DEBUG:PIL.Image:Importing ImImagePlugin
DEBUG:PIL.Image:Importing ImtImagePlugin
DEBUG:PIL.Image:Importing IptcImagePlugin
DEBUG:PIL.Image:Importing JpegImagePlugin
DEBUG:PIL.Image:Importing Jpeg2KImagePlugin
DEBUG:PIL.Image:Importing McIdasImagePlugin
DEBUG:PIL.Image:Importing MicImagePlugin
DEBUG:PIL.Image:Importing MpegImagePlugin
DEBUG:PIL.Image:Importing MpoImagePlugin
DEBUG:PIL.Image:Importing MspImagePlugin
DEBUG:PIL.Image:Importing PalmImagePlugin
DEBUG:PIL.Image:Importing PcdImagePlugin
DEBUG:PIL.Image:Importing PcxImagePlugin
DEBUG:PIL.Image:Importing PdfImagePlugin
DEBUG:PIL.Image:Importing PixarImagePlugin
DEBUG:PIL.Image:Importing PngImagePlugin
DEBUG:PIL.Image:Importing PpmImagePlugin
DEBUG:PIL.Image:Importing PsdImagePlugin
DEBUG:PIL.Image:Importing SgiImagePlugin
DEBUG:PIL.Image:Importing SpiderImagePlugin
DEBUG:PIL.Image:Importing SunImagePlugin
DEBUG:PIL.Image:Importing TgaImagePlugin
DEBUG:PIL.Image:Importing TiffImagePlugin
DEBUG:PIL.Image:Importing WebPImagePlugin
DEBUG:PIL.Image:Importing WmfImagePlugin
DEBUG:PIL.Image:Importing XbmImagePlugin
DEBUG:PIL.Image:Importing XpmImagePlugin
DEBUG:PIL.Image:Importing XVThumbImagePlugin
ERROR:django.request:Internal Server Error: /blog/post/new/
Traceback (most recent call last):
  File "C:\Users\kprud\anaconda3\lib\site-packages\django\core\handlers\exception.py", line 47, in inner
    response = get_response(request)
  File "C:\Users\kprud\anaconda3\lib\site-packages\django\core\handlers\base.py", line 186, in _get_response
    self.check_response(response, callback)
  File "C:\Users\kprud\anaconda3\lib\site-packages\django\core\handlers\base.py", line 312, in check_response
    raise ValueError(
ValueError: The view blog.views.PostCreateView didn't return an HttpResponse object. It returned an unawaited coroutine instead. You may need to add an 'await' into your view.
INFO:django.utils.autoreload:C:\Users\kprud\PycharmProjects\Project\blog\views.py changed, reloading.
DEBUG:asyncio:Using proactor: IocpProactor
INFO:django.utils.autoreload:C:\Users\kprud\PycharmProjects\Project\blog\views.py changed, reloading.
DEBUG:asyncio:Using proactor: IocpProactor
DEBUG:PIL.TiffImagePlugin:tag: Orientation (274) - type: short (3) - value: b'\x00\x01'
DEBUG:PIL.TiffImagePlugin:tag: XResolution (282) - type: rational (5) Tag Location: 34 - Data Location: 98 - value: b"\x00\n\xfc\x80\x00\x00'\x10"
DEBUG:PIL.TiffImagePlugin:tag: YResolution (283) - type: rational (5) Tag Location: 46 - Data Location: 106 - value: b"\x00\n\xfc\x80\x00\x00'\x10"
DEBUG:PIL.TiffImagePlugin:tag: ResolutionUnit (296) - type: short (3) - value: b'\x00\x02'
DEBUG:PIL.TiffImagePlugin:tag: Software (305) - type: string (2) Tag Location: 70 - Data Location: 114 - value: <table: 33 bytes>
DEBUG:PIL.TiffImagePlugin:tag: DateTime (306) - type: string (2) Tag Location: 82 - Data Location: 147 - value: b'2020:10:04 23:38:23\x00'
DEBUG:PIL.TiffImagePlugin:tag: ExifIFD (34665) - type: long (4) - value: b'\x00\x00\x00\xa8'
DEBUG:PIL.Image:Importing BlpImagePlugin
DEBUG:PIL.Image:Importing BmpImagePlugin
DEBUG:PIL.Image:Importing BufrStubImagePlugin
DEBUG:PIL.Image:Importing CurImagePlugin
DEBUG:PIL.Image:Importing DcxImagePlugin
DEBUG:PIL.Image:Importing DdsImagePlugin
DEBUG:PIL.Image:Importing EpsImagePlugin
DEBUG:PIL.Image:Importing FitsStubImagePlugin
DEBUG:PIL.Image:Importing FliImagePlugin
DEBUG:PIL.Image:Importing FpxImagePlugin
DEBUG:PIL.Image:Importing FtexImagePlugin
DEBUG:PIL.Image:Importing GbrImagePlugin
DEBUG:PIL.Image:Importing GifImagePlugin
DEBUG:PIL.Image:Importing GribStubImagePlugin
DEBUG:PIL.Image:Importing Hdf5StubImagePlugin
DEBUG:PIL.Image:Importing IcnsImagePlugin
DEBUG:PIL.Image:Importing IcoImagePlugin
DEBUG:PIL.Image:Importing ImImagePlugin
DEBUG:PIL.Image:Importing ImtImagePlugin
DEBUG:PIL.Image:Importing IptcImagePlugin
DEBUG:PIL.Image:Importing JpegImagePlugin
DEBUG:PIL.Image:Importing Jpeg2KImagePlugin
DEBUG:PIL.Image:Importing McIdasImagePlugin
DEBUG:PIL.Image:Importing MicImagePlugin
DEBUG:PIL.Image:Importing MpegImagePlugin
DEBUG:PIL.Image:Importing MpoImagePlugin
DEBUG:PIL.Image:Importing MspImagePlugin
DEBUG:PIL.Image:Importing PalmImagePlugin
DEBUG:PIL.Image:Importing PcdImagePlugin
DEBUG:PIL.Image:Importing PcxImagePlugin
DEBUG:PIL.Image:Importing PdfImagePlugin
DEBUG:PIL.Image:Importing PixarImagePlugin
DEBUG:PIL.Image:Importing PngImagePlugin
DEBUG:PIL.Image:Importing PpmImagePlugin
DEBUG:PIL.Image:Importing PsdImagePlugin
DEBUG:PIL.Image:Importing SgiImagePlugin
DEBUG:PIL.Image:Importing SpiderImagePlugin
DEBUG:PIL.Image:Importing SunImagePlugin
DEBUG:PIL.Image:Importing TgaImagePlugin
DEBUG:PIL.Image:Importing TiffImagePlugin
DEBUG:PIL.Image:Importing WebPImagePlugin
DEBUG:PIL.Image:Importing WmfImagePlugin
DEBUG:PIL.Image:Importing XbmImagePlugin
DEBUG:PIL.Image:Importing XpmImagePlugin
DEBUG:PIL.Image:Importing XVThumbImagePlugin
ERROR:django.request:Internal Server Error: /blog/post/new/
Traceback (most recent call last):
  File "C:\Users\kprud\anaconda3\lib\site-packages\django\core\handlers\exception.py", line 47, in inner
    response = get_response(request)
  File "C:\Users\kprud\anaconda3\lib\site-packages\django\core\handlers\base.py", line 186, in _get_response
    self.check_response(response, callback)
  File "C:\Users\kprud\anaconda3\lib\site-packages\django\core\handlers\base.py", line 312, in check_response
    raise ValueError(
ValueError: The view blog.views.PostCreateView didn't return an HttpResponse object. It returned an unawaited coroutine instead. You may need to add an 'await' into your view.
INFO:django.utils.autoreload:C:\Users\kprud\PycharmProjects\Project\blog\views.py changed, reloading.
DEBUG:asyncio:Using proactor: IocpProactor
DEBUG:PIL.TiffImagePlugin:tag: Orientation (274) - type: short (3) - value: b'\x00\x01'
DEBUG:PIL.TiffImagePlugin:tag: XResolution (282) - type: rational (5) Tag Location: 34 - Data Location: 98 - value: b"\x00\n\xfc\x80\x00\x00'\x10"
DEBUG:PIL.TiffImagePlugin:tag: YResolution (283) - type: rational (5) Tag Location: 46 - Data Location: 106 - value: b"\x00\n\xfc\x80\x00\x00'\x10"
DEBUG:PIL.TiffImagePlugin:tag: ResolutionUnit (296) - type: short (3) - value: b'\x00\x02'
DEBUG:PIL.TiffImagePlugin:tag: Software (305) - type: string (2) Tag Location: 70 - Data Location: 114 - value: <table: 33 bytes>
DEBUG:PIL.TiffImagePlugin:tag: DateTime (306) - type: string (2) Tag Location: 82 - Data Location: 147 - value: b'2020:10:04 23:38:23\x00'
DEBUG:PIL.TiffImagePlugin:tag: ExifIFD (34665) - type: long (4) - value: b'\x00\x00\x00\xa8'
DEBUG:PIL.Image:Importing BlpImagePlugin
DEBUG:PIL.Image:Importing BmpImagePlugin
DEBUG:PIL.Image:Importing BufrStubImagePlugin
DEBUG:PIL.Image:Importing CurImagePlugin
DEBUG:PIL.Image:Importing DcxImagePlugin
DEBUG:PIL.Image:Importing DdsImagePlugin
DEBUG:PIL.Image:Importing EpsImagePlugin
DEBUG:PIL.Image:Importing FitsStubImagePlugin
DEBUG:PIL.Image:Importing FliImagePlugin
DEBUG:PIL.Image:Importing FpxImagePlugin
DEBUG:PIL.Image:Importing FtexImagePlugin
DEBUG:PIL.Image:Importing GbrImagePlugin
DEBUG:PIL.Image:Importing GifImagePlugin
DEBUG:PIL.Image:Importing GribStubImagePlugin
DEBUG:PIL.Image:Importing Hdf5StubImagePlugin
DEBUG:PIL.Image:Importing IcnsImagePlugin
DEBUG:PIL.Image:Importing IcoImagePlugin
DEBUG:PIL.Image:Importing ImImagePlugin
DEBUG:PIL.Image:Importing ImtImagePlugin
DEBUG:PIL.Image:Importing IptcImagePlugin
DEBUG:PIL.Image:Importing JpegImagePlugin
DEBUG:PIL.Image:Importing Jpeg2KImagePlugin
DEBUG:PIL.Image:Importing McIdasImagePlugin
DEBUG:PIL.Image:Importing MicImagePlugin
DEBUG:PIL.Image:Importing MpegImagePlugin
DEBUG:PIL.Image:Importing MpoImagePlugin
DEBUG:PIL.Image:Importing MspImagePlugin
DEBUG:PIL.Image:Importing PalmImagePlugin
DEBUG:PIL.Image:Importing PcdImagePlugin
DEBUG:PIL.Image:Importing PcxImagePlugin
DEBUG:PIL.Image:Importing PdfImagePlugin
DEBUG:PIL.Image:Importing PixarImagePlugin
DEBUG:PIL.Image:Importing PngImagePlugin
DEBUG:PIL.Image:Importing PpmImagePlugin
DEBUG:PIL.Image:Importing PsdImagePlugin
DEBUG:PIL.Image:Importing SgiImagePlugin
DEBUG:PIL.Image:Importing SpiderImagePlugin
DEBUG:PIL.Image:Importing SunImagePlugin
DEBUG:PIL.Image:Importing TgaImagePlugin
DEBUG:PIL.Image:Importing TiffImagePlugin
DEBUG:PIL.Image:Importing WebPImagePlugin
DEBUG:PIL.Image:Importing WmfImagePlugin
DEBUG:PIL.Image:Importing XbmImagePlugin
DEBUG:PIL.Image:Importing XpmImagePlugin
DEBUG:PIL.Image:Importing XVThumbImagePlugin
ERROR:django.request:Internal Server Error: /blog/post/new/
Traceback (most recent call last):
  File "C:\Users\kprud\anaconda3\lib\site-packages\django\core\handlers\exception.py", line 47, in inner
    response = get_response(request)
  File "C:\Users\kprud\anaconda3\lib\site-packages\django\core\handlers\base.py", line 186, in _get_response
    self.check_response(response, callback)
  File "C:\Users\kprud\anaconda3\lib\site-packages\django\core\handlers\base.py", line 312, in check_response
    raise ValueError(
ValueError: The view blog.views.PostCreateView didn't return an HttpResponse object. It returned an unawaited coroutine instead. You may need to add an 'await' into your view.
INFO:django.utils.autoreload:C:\Users\kprud\PycharmProjects\Project\blog\views.py changed, reloading.
DEBUG:asyncio:Using proactor: IocpProactor
ERROR:django.request:Internal Server Error: /blog/post/new/
Traceback (most recent call last):
  File "C:\Users\kprud\anaconda3\lib\site-packages\django\core\handlers\exception.py", line 47, in inner
    response = get_response(request)
  File "C:\Users\kprud\anaconda3\lib\site-packages\django\core\handlers\base.py", line 186, in _get_response
    self.check_response(response, callback)
  File "C:\Users\kprud\anaconda3\lib\site-packages\django\core\handlers\base.py", line 312, in check_response
    raise ValueError(
ValueError: The view blog.views.PostCreateView didn't return an HttpResponse object. It returned an unawaited coroutine instead. You may need to add an 'await' into your view.
INFO:django.utils.autoreload:C:\Users\kprud\PycharmProjects\Project\blog\views.py changed, reloading.
DEBUG:asyncio:Using proactor: IocpProactor
ERROR:django.request:Internal Server Error: /blog/post/new/
Traceback (most recent call last):
  File "C:\Users\kprud\anaconda3\lib\site-packages\django\core\handlers\exception.py", line 47, in inner
    response = get_response(request)
  File "C:\Users\kprud\anaconda3\lib\site-packages\django\core\handlers\base.py", line 186, in _get_response
    self.check_response(response, callback)
  File "C:\Users\kprud\anaconda3\lib\site-packages\django\core\handlers\base.py", line 312, in check_response
    raise ValueError(
ValueError: The view blog.views.PostCreateView didn't return an HttpResponse object. It returned an unawaited coroutine instead. You may need to add an 'await' into your view.
INFO:django.utils.autoreload:C:\Users\kprud\PycharmProjects\Project\blog\views.py changed, reloading.
DEBUG:asyncio:Using proactor: IocpProactor
ERROR:django.request:Internal Server Error: /blog/post/new/
Traceback (most recent call last):
  File "C:\Users\kprud\anaconda3\lib\site-packages\django\core\handlers\exception.py", line 47, in inner
    response = get_response(request)
  File "C:\Users\kprud\anaconda3\lib\site-packages\django\core\handlers\base.py", line 186, in _get_response
    self.check_response(response, callback)
  File "C:\Users\kprud\anaconda3\lib\site-packages\django\core\handlers\base.py", line 312, in check_response
    raise ValueError(
ValueError: The view blog.views.PostCreateView didn't return an HttpResponse object. It returned an unawaited coroutine instead. You may need to add an 'await' into your view.
INFO:django.utils.autoreload:C:\Users\kprud\PycharmProjects\Project\blog\views.py changed, reloading.
DEBUG:asyncio:Using proactor: IocpProactor
DEBUG:urllib3.connectionpool:Starting new HTTP connection (1): api.open-notify.org:80
DEBUG:urllib3.connectionpool:http://api.open-notify.org:80 "GET /astros.json HTTP/1.1" 200 497
ERROR:django.request:Internal Server Error: /blog/post/new/
Traceback (most recent call last):
  File "C:\Users\kprud\anaconda3\lib\site-packages\django\core\handlers\exception.py", line 47, in inner
    response = get_response(request)
  File "C:\Users\kprud\anaconda3\lib\site-packages\django\core\handlers\base.py", line 179, in _get_response
    response = wrapped_callback(request, *callback_args, **callback_kwargs)
  File "C:\Users\kprud\anaconda3\lib\site-packages\django\views\generic\base.py", line 70, in view
    return self.dispatch(request, *args, **kwargs)
  File "C:\Users\kprud\anaconda3\lib\site-packages\django\contrib\auth\mixins.py", line 52, in dispatch
    return super().dispatch(request, *args, **kwargs)
  File "C:\Users\kprud\anaconda3\lib\site-packages\django\views\generic\base.py", line 98, in dispatch
    return handler(request, *args, **kwargs)
  File "C:\Users\kprud\anaconda3\lib\site-packages\django\views\generic\edit.py", line 172, in post
    return super().post(request, *args, **kwargs)
  File "C:\Users\kprud\anaconda3\lib\site-packages\django\views\generic\edit.py", line 142, in post
    return self.form_valid(form)
  File "C:\Users\kprud\PycharmProjects\Project\blog\views.py", line 58, in form_valid
    form.instance.content =response.json().q
AttributeError: 'dict' object has no attribute 'q'
INFO:django.utils.autoreload:C:\Users\kprud\PycharmProjects\Project\blog\views.py changed, reloading.
DEBUG:asyncio:Using proactor: IocpProactor
DEBUG:urllib3.connectionpool:Starting new HTTP connection (1): api.open-notify.org:80
DEBUG:urllib3.connectionpool:http://api.open-notify.org:80 "GET /astros.json HTTP/1.1" 200 497
DEBUG:root:prudhvi
DEBUG:root:k.prudhvireddy1996@gmail.com
INFO:django.utils.autoreload:C:\Users\kprud\PycharmProjects\Project\blog\views.py changed, reloading.
DEBUG:asyncio:Using proactor: IocpProactor
DEBUG:urllib3.connectionpool:Starting new HTTPS connection (1): zenquotes.io:443
DEBUG:urllib3.connectionpool:https://zenquotes.io:443 "GET /api/today HTTP/1.1" 200 None
ERROR:django.request:Internal Server Error: /blog/post/new/
Traceback (most recent call last):
  File "C:\Users\kprud\anaconda3\lib\site-packages\django\core\handlers\exception.py", line 47, in inner
    response = get_response(request)
  File "C:\Users\kprud\anaconda3\lib\site-packages\django\core\handlers\base.py", line 179, in _get_response
    response = wrapped_callback(request, *callback_args, **callback_kwargs)
  File "C:\Users\kprud\anaconda3\lib\site-packages\django\views\generic\base.py", line 70, in view
    return self.dispatch(request, *args, **kwargs)
  File "C:\Users\kprud\anaconda3\lib\site-packages\django\contrib\auth\mixins.py", line 52, in dispatch
    return super().dispatch(request, *args, **kwargs)
  File "C:\Users\kprud\anaconda3\lib\site-packages\django\views\generic\base.py", line 98, in dispatch
    return handler(request, *args, **kwargs)
  File "C:\Users\kprud\anaconda3\lib\site-packages\django\views\generic\edit.py", line 172, in post
    return super().post(request, *args, **kwargs)
  File "C:\Users\kprud\anaconda3\lib\site-packages\django\views\generic\edit.py", line 142, in post
    return self.form_valid(form)
  File "C:\Users\kprud\PycharmProjects\Project\blog\views.py", line 58, in form_valid
    form.instance.content =response.json().q
AttributeError: 'list' object has no attribute 'q'
INFO:django.utils.autoreload:C:\Users\kprud\PycharmProjects\Project\blog\views.py changed, reloading.
DEBUG:asyncio:Using proactor: IocpProactor
DEBUG:urllib3.connectionpool:Starting new HTTPS connection (1): zenquotes.io:443
DEBUG:urllib3.connectionpool:https://zenquotes.io:443 "GET /api/today HTTP/1.1" 200 None
DEBUG:root:prudhvi
DEBUG:root:k.prudhvireddy1996@gmail.com
INFO:django.utils.autoreload:C:\Users\kprud\PycharmProjects\Project\blog\views.py changed, reloading.
DEBUG:asyncio:Using proactor: IocpProactor
DEBUG:PIL.Image:Importing BlpImagePlugin
DEBUG:PIL.Image:Importing BmpImagePlugin
DEBUG:PIL.Image:Importing BufrStubImagePlugin
DEBUG:PIL.Image:Importing CurImagePlugin
DEBUG:PIL.Image:Importing DcxImagePlugin
DEBUG:PIL.Image:Importing DdsImagePlugin
DEBUG:PIL.Image:Importing EpsImagePlugin
DEBUG:PIL.Image:Importing FitsStubImagePlugin
DEBUG:PIL.Image:Importing FliImagePlugin
DEBUG:PIL.Image:Importing FpxImagePlugin
DEBUG:PIL.Image:Importing FtexImagePlugin
DEBUG:PIL.Image:Importing GbrImagePlugin
DEBUG:PIL.Image:Importing GifImagePlugin
DEBUG:PIL.Image:Importing GribStubImagePlugin
DEBUG:PIL.Image:Importing Hdf5StubImagePlugin
DEBUG:PIL.Image:Importing IcnsImagePlugin
DEBUG:PIL.Image:Importing IcoImagePlugin
DEBUG:PIL.Image:Importing ImImagePlugin
DEBUG:PIL.Image:Importing ImtImagePlugin
DEBUG:PIL.Image:Importing IptcImagePlugin
DEBUG:PIL.Image:Importing JpegImagePlugin
DEBUG:PIL.Image:Importing Jpeg2KImagePlugin
DEBUG:PIL.Image:Importing McIdasImagePlugin
DEBUG:PIL.Image:Importing MicImagePlugin
DEBUG:PIL.Image:Importing MpegImagePlugin
DEBUG:PIL.Image:Importing MpoImagePlugin
DEBUG:PIL.Image:Importing MspImagePlugin
DEBUG:PIL.Image:Importing PalmImagePlugin
DEBUG:PIL.Image:Importing PcdImagePlugin
DEBUG:PIL.Image:Importing PcxImagePlugin
DEBUG:PIL.Image:Importing PdfImagePlugin
DEBUG:PIL.Image:Importing PixarImagePlugin
DEBUG:PIL.Image:Importing PngImagePlugin
DEBUG:PIL.Image:Importing PpmImagePlugin
DEBUG:PIL.Image:Importing PsdImagePlugin
DEBUG:PIL.Image:Importing SgiImagePlugin
DEBUG:PIL.Image:Importing SpiderImagePlugin
DEBUG:PIL.Image:Importing SunImagePlugin
DEBUG:PIL.Image:Importing TgaImagePlugin
DEBUG:PIL.Image:Importing TiffImagePlugin
DEBUG:PIL.Image:Importing WebPImagePlugin
DEBUG:PIL.Image:Importing WmfImagePlugin
DEBUG:PIL.Image:Importing XbmImagePlugin
DEBUG:PIL.Image:Importing XpmImagePlugin
DEBUG:PIL.Image:Importing XVThumbImagePlugin
DEBUG:urllib3.connectionpool:Starting new HTTPS connection (1): zenquotes.io:443
DEBUG:urllib3.connectionpool:https://zenquotes.io:443 "GET /api/today HTTP/1.1" 200 None
ERROR:django.request:Internal Server Error: /blog/post/new/
Traceback (most recent call last):
  File "C:\Users\kprud\anaconda3\lib\site-packages\django\core\handlers\exception.py", line 47, in inner
    response = get_response(request)
  File "C:\Users\kprud\anaconda3\lib\site-packages\django\core\handlers\base.py", line 179, in _get_response
    response = wrapped_callback(request, *callback_args, **callback_kwargs)
  File "C:\Users\kprud\anaconda3\lib\site-packages\django\views\generic\base.py", line 70, in view
    return self.dispatch(request, *args, **kwargs)
  File "C:\Users\kprud\anaconda3\lib\site-packages\django\contrib\auth\mixins.py", line 52, in dispatch
    return super().dispatch(request, *args, **kwargs)
  File "C:\Users\kprud\anaconda3\lib\site-packages\django\views\generic\base.py", line 98, in dispatch
    return handler(request, *args, **kwargs)
  File "C:\Users\kprud\anaconda3\lib\site-packages\django\views\generic\edit.py", line 172, in post
    return super().post(request, *args, **kwargs)
  File "C:\Users\kprud\anaconda3\lib\site-packages\django\views\generic\edit.py", line 142, in post
    return self.form_valid(form)
  File "C:\Users\kprud\PycharmProjects\Project\blog\views.py", line 58, in form_valid
    form.instance.content =response.json()[0].q
AttributeError: 'dict' object has no attribute 'q'
INFO:django.utils.autoreload:C:\Users\kprud\PycharmProjects\Project\blog\views.py changed, reloading.
DEBUG:asyncio:Using proactor: IocpProactor
DEBUG:PIL.Image:Importing BlpImagePlugin
DEBUG:PIL.Image:Importing BmpImagePlugin
DEBUG:PIL.Image:Importing BufrStubImagePlugin
DEBUG:PIL.Image:Importing CurImagePlugin
DEBUG:PIL.Image:Importing DcxImagePlugin
DEBUG:PIL.Image:Importing DdsImagePlugin
DEBUG:PIL.Image:Importing EpsImagePlugin
DEBUG:PIL.Image:Importing FitsStubImagePlugin
DEBUG:PIL.Image:Importing FliImagePlugin
DEBUG:PIL.Image:Importing FpxImagePlugin
DEBUG:PIL.Image:Importing FtexImagePlugin
DEBUG:PIL.Image:Importing GbrImagePlugin
DEBUG:PIL.Image:Importing GifImagePlugin
DEBUG:PIL.Image:Importing GribStubImagePlugin
DEBUG:PIL.Image:Importing Hdf5StubImagePlugin
DEBUG:PIL.Image:Importing IcnsImagePlugin
DEBUG:PIL.Image:Importing IcoImagePlugin
DEBUG:PIL.Image:Importing ImImagePlugin
DEBUG:PIL.Image:Importing ImtImagePlugin
DEBUG:PIL.Image:Importing IptcImagePlugin
DEBUG:PIL.Image:Importing JpegImagePlugin
DEBUG:PIL.Image:Importing Jpeg2KImagePlugin
DEBUG:PIL.Image:Importing McIdasImagePlugin
DEBUG:PIL.Image:Importing MicImagePlugin
DEBUG:PIL.Image:Importing MpegImagePlugin
DEBUG:PIL.Image:Importing MpoImagePlugin
DEBUG:PIL.Image:Importing MspImagePlugin
DEBUG:PIL.Image:Importing PalmImagePlugin
DEBUG:PIL.Image:Importing PcdImagePlugin
DEBUG:PIL.Image:Importing PcxImagePlugin
DEBUG:PIL.Image:Importing PdfImagePlugin
DEBUG:PIL.Image:Importing PixarImagePlugin
DEBUG:PIL.Image:Importing PngImagePlugin
DEBUG:PIL.Image:Importing PpmImagePlugin
DEBUG:PIL.Image:Importing PsdImagePlugin
DEBUG:PIL.Image:Importing SgiImagePlugin
DEBUG:PIL.Image:Importing SpiderImagePlugin
DEBUG:PIL.Image:Importing SunImagePlugin
DEBUG:PIL.Image:Importing TgaImagePlugin
DEBUG:PIL.Image:Importing TiffImagePlugin
DEBUG:PIL.Image:Importing WebPImagePlugin
DEBUG:PIL.Image:Importing WmfImagePlugin
DEBUG:PIL.Image:Importing XbmImagePlugin
DEBUG:PIL.Image:Importing XpmImagePlugin
DEBUG:PIL.Image:Importing XVThumbImagePlugin
DEBUG:urllib3.connectionpool:Starting new HTTPS connection (1): zenquotes.io:443
DEBUG:urllib3.connectionpool:https://zenquotes.io:443 "GET /api/today HTTP/1.1" 200 None
DEBUG:root:prudhvi
DEBUG:root:k.prudhvireddy1996@gmail.com
DEBUG:urllib3.connectionpool:Starting new HTTPS connection (1): zenquotes.io:443
DEBUG:urllib3.connectionpool:https://zenquotes.io:443 "GET /api/today HTTP/1.1" 200 None
DEBUG:root:prudhvi
DEBUG:root:k.prudhvireddy1996@gmail.com
INFO:django.utils.autoreload:C:\Users\kprud\PycharmProjects\Project\blog\views.py changed, reloading.
DEBUG:asyncio:Using proactor: IocpProactor
INFO:django.utils.autoreload:C:\Users\kprud\PycharmProjects\Project\blog\views.py changed, reloading.
DEBUG:asyncio:Using proactor: IocpProactor
INFO:django.utils.autoreload:C:\Users\kprud\PycharmProjects\Project\blog\views.py changed, reloading.
DEBUG:asyncio:Using proactor: IocpProactor
DEBUG:urllib3.connectionpool:Starting new HTTPS connection (1): zenquotes.io:443
DEBUG:urllib3.connectionpool:https://zenquotes.io:443 "GET /api/random HTTP/1.1" 200 None
INFO:django.utils.autoreload:C:\Users\kprud\PycharmProjects\Project\blog\views.py changed, reloading.
DEBUG:asyncio:Using proactor: IocpProactor
ERROR:django.request:Internal Server Error: /blog/post/39/update/
Traceback (most recent call last):
  File "C:\Users\kprud\anaconda3\lib\site-packages\django\core\handlers\exception.py", line 47, in inner
    response = get_response(request)
  File "C:\Users\kprud\anaconda3\lib\site-packages\django\core\handlers\base.py", line 186, in _get_response
    self.check_response(response, callback)
  File "C:\Users\kprud\anaconda3\lib\site-packages\django\core\handlers\base.py", line 312, in check_response
    raise ValueError(
ValueError: The view blog.views.PostUpdateView didn't return an HttpResponse object. It returned an unawaited coroutine instead. You may need to add an 'await' into your view.
INFO:django.utils.autoreload:C:\Users\kprud\PycharmProjects\Project\blog\views.py changed, reloading.
DEBUG:asyncio:Using proactor: IocpProactor
DEBUG:urllib3.connectionpool:Starting new HTTPS connection (1): zenquotes.io:443
DEBUG:urllib3.connectionpool:https://zenquotes.io:443 "GET /api/random HTTP/1.1" 200 None
INFO:django.utils.autoreload:C:\Users\kprud\PycharmProjects\Project\blog\models.py changed, reloading.
DEBUG:asyncio:Using proactor: IocpProactor
DEBUG:urllib3.connectionpool:Starting new HTTPS connection (1): zenquotes.io:443
DEBUG:urllib3.connectionpool:https://zenquotes.io:443 "GET /api/random HTTP/1.1" 200 None
DEBUG:root:prudhvi
DEBUG:root:k.prudhvireddy1996@gmail.com
ERROR:django.request:Internal Server Error: /blog/post/new/
Traceback (most recent call last):
  File "C:\Users\kprud\anaconda3\lib\site-packages\django\core\handlers\exception.py", line 47, in inner
    response = get_response(request)
  File "C:\Users\kprud\anaconda3\lib\site-packages\django\core\handlers\base.py", line 179, in _get_response
    response = wrapped_callback(request, *callback_args, **callback_kwargs)
  File "C:\Users\kprud\anaconda3\lib\site-packages\django\views\generic\base.py", line 70, in view
    return self.dispatch(request, *args, **kwargs)
  File "C:\Users\kprud\anaconda3\lib\site-packages\django\contrib\auth\mixins.py", line 52, in dispatch
    return super().dispatch(request, *args, **kwargs)
  File "C:\Users\kprud\anaconda3\lib\site-packages\django\views\generic\base.py", line 98, in dispatch
    return handler(request, *args, **kwargs)
  File "C:\Users\kprud\anaconda3\lib\site-packages\django\views\generic\edit.py", line 172, in post
    return super().post(request, *args, **kwargs)
  File "C:\Users\kprud\anaconda3\lib\site-packages\django\views\generic\edit.py", line 142, in post
    return self.form_valid(form)
  File "C:\Users\kprud\PycharmProjects\Project\blog\views.py", line 64, in form_valid
    return super().form_valid(form)
  File "C:\Users\kprud\anaconda3\lib\site-packages\django\views\generic\edit.py", line 125, in form_valid
    self.object = form.save()
  File "C:\Users\kprud\anaconda3\lib\site-packages\django\forms\models.py", line 460, in save
    self.instance.save()
  File "C:\Users\kprud\PycharmProjects\Project\blog\models.py", line 25, in save
    img=Image.open(self.fruit_pic.path)
  File "C:\Users\kprud\anaconda3\lib\site-packages\PIL\Image.py", line 2975, in open
    fp = builtins.open(filename, "rb")
OSError: [Errno 22] Invalid argument: 'C:\\Users\\kprud\\PycharmProjects\\Project\\media\\https:\\source.unsplash.com\\random\\300x200?sig=${Math.random()}'
INFO:django.utils.autoreload:C:\Users\kprud\PycharmProjects\Project\blog\models.py changed, reloading.
DEBUG:asyncio:Using proactor: IocpProactor
INFO:django.utils.autoreload:C:\Users\kprud\PycharmProjects\Project\blog\models.py changed, reloading.
DEBUG:asyncio:Using proactor: IocpProactor
INFO:django.utils.autoreload:C:\Users\kprud\PycharmProjects\Project\blog\views.py changed, reloading.
DEBUG:asyncio:Using proactor: IocpProactor
WARNING:django.request:Not Found: /media/https:/source.unsplash.com/random/300x200?sig=${Math.random()}
WARNING:django.request:Not Found: /media/https:/source.unsplash.com/random/300x200?sig=${Math.random()}
WARNING:django.request:Not Found: /media/https:/source.unsplash.com/random/300x200?sig=${Math.random()}
DEBUG:urllib3.connectionpool:Starting new HTTPS connection (1): zenquotes.io:443
DEBUG:urllib3.connectionpool:https://zenquotes.io:443 "GET /api/random HTTP/1.1" 200 None
DEBUG:root:prudhvi
DEBUG:root:k.prudhvireddy1996@gmail.com
ERROR:django.request:Internal Server Error: /blog/post/new/
Traceback (most recent call last):
  File "C:\Users\kprud\anaconda3\lib\site-packages\django\core\handlers\exception.py", line 47, in inner
    response = get_response(request)
  File "C:\Users\kprud\anaconda3\lib\site-packages\django\core\handlers\base.py", line 179, in _get_response
    response = wrapped_callback(request, *callback_args, **callback_kwargs)
  File "C:\Users\kprud\anaconda3\lib\site-packages\django\views\generic\base.py", line 70, in view
    return self.dispatch(request, *args, **kwargs)
  File "C:\Users\kprud\anaconda3\lib\site-packages\django\contrib\auth\mixins.py", line 52, in dispatch
    return super().dispatch(request, *args, **kwargs)
  File "C:\Users\kprud\anaconda3\lib\site-packages\django\views\generic\base.py", line 98, in dispatch
    return handler(request, *args, **kwargs)
  File "C:\Users\kprud\anaconda3\lib\site-packages\django\views\generic\edit.py", line 172, in post
    return super().post(request, *args, **kwargs)
  File "C:\Users\kprud\anaconda3\lib\site-packages\django\views\generic\edit.py", line 142, in post
    return self.form_valid(form)
  File "C:\Users\kprud\PycharmProjects\Project\blog\views.py", line 66, in form_valid
    return super().form_valid(form)
  File "C:\Users\kprud\anaconda3\lib\site-packages\django\views\generic\edit.py", line 125, in form_valid
    self.object = form.save()
  File "C:\Users\kprud\anaconda3\lib\site-packages\django\forms\models.py", line 460, in save
    self.instance.save()
  File "C:\Users\kprud\PycharmProjects\Project\blog\models.py", line 25, in save
    img=Image.open(self.fruit_pic.path)
  File "C:\Users\kprud\anaconda3\lib\site-packages\django\db\models\fields\files.py", line 56, in path
    self._require_file()
  File "C:\Users\kprud\anaconda3\lib\site-packages\django\db\models\fields\files.py", line 38, in _require_file
    raise ValueError("The '%s' attribute has no file associated with it." % self.field.name)
ValueError: The 'fruit_pic' attribute has no file associated with it.
INFO:django.utils.autoreload:C:\Users\kprud\PycharmProjects\Project\blog\views.py changed, reloading.
DEBUG:asyncio:Using proactor: IocpProactor
INFO:django.utils.autoreload:C:\Users\kprud\PycharmProjects\Project\blog\views.py changed, reloading.
DEBUG:asyncio:Using proactor: IocpProactor
DEBUG:urllib3.connectionpool:Starting new HTTPS connection (1): zenquotes.io:443
DEBUG:urllib3.connectionpool:https://zenquotes.io:443 "GET /api/random HTTP/1.1" 200 None
DEBUG:root:prudhvi
DEBUG:root:k.prudhvireddy1996@gmail.com
ERROR:django.request:Internal Server Error: /blog/post/new/
Traceback (most recent call last):
  File "C:\Users\kprud\anaconda3\lib\site-packages\django\core\handlers\exception.py", line 47, in inner
    response = get_response(request)
  File "C:\Users\kprud\anaconda3\lib\site-packages\django\core\handlers\base.py", line 179, in _get_response
    response = wrapped_callback(request, *callback_args, **callback_kwargs)
  File "C:\Users\kprud\anaconda3\lib\site-packages\django\views\generic\base.py", line 70, in view
    return self.dispatch(request, *args, **kwargs)
  File "C:\Users\kprud\anaconda3\lib\site-packages\django\contrib\auth\mixins.py", line 52, in dispatch
    return super().dispatch(request, *args, **kwargs)
  File "C:\Users\kprud\anaconda3\lib\site-packages\django\views\generic\base.py", line 98, in dispatch
    return handler(request, *args, **kwargs)
  File "C:\Users\kprud\anaconda3\lib\site-packages\django\views\generic\edit.py", line 172, in post
    return super().post(request, *args, **kwargs)
  File "C:\Users\kprud\anaconda3\lib\site-packages\django\views\generic\edit.py", line 142, in post
    return self.form_valid(form)
  File "C:\Users\kprud\PycharmProjects\Project\blog\views.py", line 67, in form_valid
    return super().form_valid(form)
  File "C:\Users\kprud\anaconda3\lib\site-packages\django\views\generic\edit.py", line 125, in form_valid
    self.object = form.save()
  File "C:\Users\kprud\anaconda3\lib\site-packages\django\forms\models.py", line 460, in save
    self.instance.save()
  File "C:\Users\kprud\PycharmProjects\Project\blog\models.py", line 25, in save
    img=Image.open(self.fruit_pic.path)
  File "C:\Users\kprud\anaconda3\lib\site-packages\django\db\models\fields\files.py", line 56, in path
    self._require_file()
  File "C:\Users\kprud\anaconda3\lib\site-packages\django\db\models\fields\files.py", line 38, in _require_file
    raise ValueError("The '%s' attribute has no file associated with it." % self.field.name)
ValueError: The 'fruit_pic' attribute has no file associated with it.
INFO:django.utils.autoreload:C:\Users\kprud\PycharmProjects\Project\blog\views.py changed, reloading.
DEBUG:asyncio:Using proactor: IocpProactor
INFO:django.utils.autoreload:C:\Users\kprud\PycharmProjects\Project\blog\models.py changed, reloading.
DEBUG:asyncio:Using proactor: IocpProactor
DEBUG:urllib3.connectionpool:Starting new HTTPS connection (1): zenquotes.io:443
DEBUG:urllib3.connectionpool:https://zenquotes.io:443 "GET /api/random HTTP/1.1" 200 None
DEBUG:root:prudhvi
DEBUG:root:k.prudhvireddy1996@gmail.com
WARNING:django.request:Not Found: /media/https:/source.unsplash.com/random/300x200?sig=${Math.random()}
DEBUG:PIL.Image:Importing BlpImagePlugin
DEBUG:PIL.Image:Importing BmpImagePlugin
DEBUG:PIL.Image:Importing BufrStubImagePlugin
DEBUG:PIL.Image:Importing CurImagePlugin
DEBUG:PIL.Image:Importing DcxImagePlugin
DEBUG:PIL.Image:Importing DdsImagePlugin
DEBUG:PIL.Image:Importing EpsImagePlugin
DEBUG:PIL.Image:Importing FitsStubImagePlugin
DEBUG:PIL.Image:Importing FliImagePlugin
DEBUG:PIL.Image:Importing FpxImagePlugin
DEBUG:PIL.Image:Importing FtexImagePlugin
DEBUG:PIL.Image:Importing GbrImagePlugin
DEBUG:PIL.Image:Importing GifImagePlugin
DEBUG:PIL.Image:Importing GribStubImagePlugin
DEBUG:PIL.Image:Importing Hdf5StubImagePlugin
DEBUG:PIL.Image:Importing IcnsImagePlugin
DEBUG:PIL.Image:Importing IcoImagePlugin
DEBUG:PIL.Image:Importing ImImagePlugin
DEBUG:PIL.Image:Importing ImtImagePlugin
DEBUG:PIL.Image:Importing IptcImagePlugin
DEBUG:PIL.Image:Importing JpegImagePlugin
DEBUG:PIL.Image:Importing Jpeg2KImagePlugin
DEBUG:PIL.Image:Importing McIdasImagePlugin
DEBUG:PIL.Image:Importing MicImagePlugin
DEBUG:PIL.Image:Importing MpegImagePlugin
DEBUG:PIL.Image:Importing MpoImagePlugin
DEBUG:PIL.Image:Importing MspImagePlugin
DEBUG:PIL.Image:Importing PalmImagePlugin
DEBUG:PIL.Image:Importing PcdImagePlugin
DEBUG:PIL.Image:Importing PcxImagePlugin
DEBUG:PIL.Image:Importing PdfImagePlugin
DEBUG:PIL.Image:Importing PixarImagePlugin
DEBUG:PIL.Image:Importing PngImagePlugin
DEBUG:PIL.Image:Importing PpmImagePlugin
DEBUG:PIL.Image:Importing PsdImagePlugin
DEBUG:PIL.Image:Importing SgiImagePlugin
DEBUG:PIL.Image:Importing SpiderImagePlugin
DEBUG:PIL.Image:Importing SunImagePlugin
DEBUG:PIL.Image:Importing TgaImagePlugin
DEBUG:PIL.Image:Importing TiffImagePlugin
DEBUG:PIL.Image:Importing WebPImagePlugin
DEBUG:PIL.Image:Importing WmfImagePlugin
DEBUG:PIL.Image:Importing XbmImagePlugin
DEBUG:PIL.Image:Importing XpmImagePlugin
DEBUG:PIL.Image:Importing XVThumbImagePlugin
WARNING:django.request:Not Found: /media/https:/source.unsplash.com/random/300x200?sig=${Math.random()}
WARNING:django.request:Not Found: /media/https:/source.unsplash.com/random/300x200?sig=${Math.random()}
INFO:django.utils.autoreload:C:\Users\kprud\PycharmProjects\Project\users\models.py changed, reloading.
DEBUG:asyncio:Using proactor: IocpProactor
INFO:django.utils.autoreload:C:\Users\kprud\PycharmProjects\Project\users\models.py changed, reloading.
DEBUG:asyncio:Using proactor: IocpProactor
INFO:django.utils.autoreload:C:\Users\kprud\PycharmProjects\Project\users\models.py changed, reloading.
DEBUG:asyncio:Using proactor: IocpProactor
INFO:django.utils.autoreload:C:\Users\kprud\PycharmProjects\Project\users\models.py changed, reloading.
DEBUG:asyncio:Using proactor: IocpProactor
INFO:django.utils.autoreload:C:\Users\kprud\PycharmProjects\Project\users\forms.py changed, reloading.
DEBUG:asyncio:Using proactor: IocpProactor
INFO:django.utils.autoreload:C:\Users\kprud\PycharmProjects\Project\users\forms.py changed, reloading.
DEBUG:asyncio:Using proactor: IocpProactor
INFO:django.utils.autoreload:C:\Users\kprud\PycharmProjects\Project\users\models.py changed, reloading.
DEBUG:asyncio:Using proactor: IocpProactor
INFO:django.utils.autoreload:C:\Users\kprud\PycharmProjects\Project\users\views.py changed, reloading.
DEBUG:asyncio:Using proactor: IocpProactor
DEBUG:asyncio:Using proactor: IocpProactor
DEBUG:asyncio:Using proactor: IocpProactor
DEBUG:asyncio:Using proactor: IocpProactor
WARNING:django.request:Not Found: /media/https:/source.unsplash.com/random/300x200?sig=${Math.random()}
ERROR:django.request:Internal Server Error: /profile/
Traceback (most recent call last):
  File "C:\Users\kprud\anaconda3\lib\site-packages\django\core\handlers\exception.py", line 47, in inner
    response = get_response(request)
  File "C:\Users\kprud\anaconda3\lib\site-packages\django\core\handlers\base.py", line 179, in _get_response
    response = wrapped_callback(request, *callback_args, **callback_kwargs)
  File "C:\Users\kprud\anaconda3\lib\site-packages\django\contrib\auth\decorators.py", line 21, in _wrapped_view
    return view_func(request, *args, **kwargs)
  File "C:\Users\kprud\PycharmProjects\Project\users\views.py", line 59, in profile
    d_form=DOBUpdateForm(instance=request.user.dobdetail)
  File "C:\Users\kprud\anaconda3\lib\site-packages\django\utils\functional.py", line 241, in inner
    return func(self._wrapped, *args)
  File "C:\Users\kprud\anaconda3\lib\site-packages\django\db\models\fields\related_descriptors.py", line 421, in __get__
    raise self.RelatedObjectDoesNotExist(
django.contrib.auth.models.User.dobdetail.RelatedObjectDoesNotExist: User has no dobdetail.
WARNING:django.request:Not Found: /media/https:/source.unsplash.com/random/300x200?sig=${Math.random()}
ERROR:django.request:Internal Server Error: /profile/
Traceback (most recent call last):
  File "C:\Users\kprud\anaconda3\lib\site-packages\django\core\handlers\exception.py", line 47, in inner
    response = get_response(request)
  File "C:\Users\kprud\anaconda3\lib\site-packages\django\core\handlers\base.py", line 179, in _get_response
    response = wrapped_callback(request, *callback_args, **callback_kwargs)
  File "C:\Users\kprud\anaconda3\lib\site-packages\django\contrib\auth\decorators.py", line 21, in _wrapped_view
    return view_func(request, *args, **kwargs)
  File "C:\Users\kprud\PycharmProjects\Project\users\views.py", line 59, in profile
    d_form=DOBUpdateForm(instance=request.user.dobdetail)
  File "C:\Users\kprud\anaconda3\lib\site-packages\django\utils\functional.py", line 241, in inner
    return func(self._wrapped, *args)
  File "C:\Users\kprud\anaconda3\lib\site-packages\django\db\models\fields\related_descriptors.py", line 421, in __get__
    raise self.RelatedObjectDoesNotExist(
django.contrib.auth.models.User.dobdetail.RelatedObjectDoesNotExist: User has no dobdetail.
INFO:django.utils.autoreload:C:\Users\kprud\PycharmProjects\Project\users\views.py changed, reloading.
DEBUG:asyncio:Using proactor: IocpProactor
ERROR:django.request:Internal Server Error: /profile/
Traceback (most recent call last):
  File "C:\Users\kprud\anaconda3\lib\site-packages\django\core\handlers\exception.py", line 47, in inner
    response = get_response(request)
  File "C:\Users\kprud\anaconda3\lib\site-packages\django\core\handlers\base.py", line 179, in _get_response
    response = wrapped_callback(request, *callback_args, **callback_kwargs)
  File "C:\Users\kprud\anaconda3\lib\site-packages\django\contrib\auth\decorators.py", line 21, in _wrapped_view
    return view_func(request, *args, **kwargs)
  File "C:\Users\kprud\PycharmProjects\Project\users\views.py", line 59, in profile
    d_form=DOBUpdateForm(instance=request.user.dob)
  File "C:\Users\kprud\anaconda3\lib\site-packages\django\utils\functional.py", line 241, in inner
    return func(self._wrapped, *args)
AttributeError: 'User' object has no attribute 'dob'
INFO:django.utils.autoreload:C:\Users\kprud\PycharmProjects\Project\users\views.py changed, reloading.
DEBUG:asyncio:Using proactor: IocpProactor
INFO:django.utils.autoreload:C:\Users\kprud\PycharmProjects\Project\users\views.py changed, reloading.
DEBUG:asyncio:Using proactor: IocpProactor
WARNING:django.request:Not Found: /media/https:/source.unsplash.com/random/300x200?sig=${Math.random()}
ERROR:django.request:Internal Server Error: /profile/
Traceback (most recent call last):
  File "C:\Users\kprud\anaconda3\lib\site-packages\django\core\handlers\exception.py", line 47, in inner
    response = get_response(request)
  File "C:\Users\kprud\anaconda3\lib\site-packages\django\core\handlers\base.py", line 179, in _get_response
    response = wrapped_callback(request, *callback_args, **callback_kwargs)
  File "C:\Users\kprud\anaconda3\lib\site-packages\django\contrib\auth\decorators.py", line 21, in _wrapped_view
    return view_func(request, *args, **kwargs)
  File "C:\Users\kprud\PycharmProjects\Project\users\views.py", line 59, in profile
    d_form=DOBUpdateForm(instance=request.user.DOBDetail)
  File "C:\Users\kprud\anaconda3\lib\site-packages\django\utils\functional.py", line 241, in inner
    return func(self._wrapped, *args)
AttributeError: 'User' object has no attribute 'DOBDetail'
INFO:django.utils.autoreload:C:\Users\kprud\PycharmProjects\Project\users\views.py changed, reloading.
DEBUG:asyncio:Using proactor: IocpProactor
INFO:django.utils.autoreload:C:\Users\kprud\PycharmProjects\Project\users\views.py changed, reloading.
DEBUG:asyncio:Using proactor: IocpProactor
WARNING:django.request:Not Found: /media/https:/source.unsplash.com/random/300x200?sig=${Math.random()}
WARNING:django.request:Not Found: /media/https:/source.unsplash.com/random/300x200?sig=${Math.random()}
ERROR:django.request:Internal Server Error: /
Traceback (most recent call last):
  File "C:\Users\kprud\anaconda3\lib\site-packages\django\core\handlers\exception.py", line 47, in inner
    response = get_response(request)
  File "C:\Users\kprud\anaconda3\lib\site-packages\django\core\handlers\base.py", line 179, in _get_response
    response = wrapped_callback(request, *callback_args, **callback_kwargs)
  File "C:\Users\kprud\anaconda3\lib\site-packages\django\views\generic\base.py", line 70, in view
    return self.dispatch(request, *args, **kwargs)
  File "C:\Users\kprud\anaconda3\lib\site-packages\django\views\generic\base.py", line 98, in dispatch
    return handler(request, *args, **kwargs)
  File "C:\Users\kprud\PycharmProjects\Project\users\views.py", line 37, in post
    print(username.dob)
AttributeError: 'str' object has no attribute 'dob'
INFO:django.utils.autoreload:C:\Users\kprud\PycharmProjects\Project\users\views.py changed, reloading.
DEBUG:asyncio:Using proactor: IocpProactor
WARNING:django.request:Not Found: /media/https:/source.unsplash.com/random/300x200?sig=${Math.random()}
WARNING:django.request:Not Found: /media/https:/source.unsplash.com/random/300x200?sig=${Math.random()}
ERROR:django.request:Internal Server Error: /profile/
Traceback (most recent call last):
  File "C:\Users\kprud\anaconda3\lib\site-packages\django\core\handlers\exception.py", line 47, in inner
    response = get_response(request)
  File "C:\Users\kprud\anaconda3\lib\site-packages\django\core\handlers\base.py", line 179, in _get_response
    response = wrapped_callback(request, *callback_args, **callback_kwargs)
  File "C:\Users\kprud\anaconda3\lib\site-packages\django\contrib\auth\decorators.py", line 21, in _wrapped_view
    return view_func(request, *args, **kwargs)
  File "C:\Users\kprud\PycharmProjects\Project\users\views.py", line 59, in profile
    d_form=DOBUpdateForm(instance=request.user.dobdetail)
  File "C:\Users\kprud\anaconda3\lib\site-packages\django\utils\functional.py", line 241, in inner
    return func(self._wrapped, *args)
  File "C:\Users\kprud\anaconda3\lib\site-packages\django\db\models\fields\related_descriptors.py", line 421, in __get__
    raise self.RelatedObjectDoesNotExist(
django.contrib.auth.models.User.dobdetail.RelatedObjectDoesNotExist: User has no dobdetail.
WARNING:django.request:Not Found: /media/https:/source.unsplash.com/random/300x200?sig=${Math.random()}
ERROR:django.request:Internal Server Error: /profile/
Traceback (most recent call last):
  File "C:\Users\kprud\anaconda3\lib\site-packages\django\core\handlers\exception.py", line 47, in inner
    response = get_response(request)
  File "C:\Users\kprud\anaconda3\lib\site-packages\django\core\handlers\base.py", line 179, in _get_response
    response = wrapped_callback(request, *callback_args, **callback_kwargs)
  File "C:\Users\kprud\anaconda3\lib\site-packages\django\contrib\auth\decorators.py", line 21, in _wrapped_view
    return view_func(request, *args, **kwargs)
  File "C:\Users\kprud\PycharmProjects\Project\users\views.py", line 59, in profile
    d_form=DOBUpdateForm(instance=request.user.dobdetail)
  File "C:\Users\kprud\anaconda3\lib\site-packages\django\utils\functional.py", line 241, in inner
    return func(self._wrapped, *args)
  File "C:\Users\kprud\anaconda3\lib\site-packages\django\db\models\fields\related_descriptors.py", line 421, in __get__
    raise self.RelatedObjectDoesNotExist(
django.contrib.auth.models.User.dobdetail.RelatedObjectDoesNotExist: User has no dobdetail.
INFO:django.utils.autoreload:C:\Users\kprud\PycharmProjects\Project\users\admin.py changed, reloading.
DEBUG:asyncio:Using proactor: IocpProactor
INFO:django.utils.autoreload:C:\Users\kprud\PycharmProjects\Project\users\views.py changed, reloading.
DEBUG:asyncio:Using proactor: IocpProactor
INFO:django.utils.autoreload:C:\Users\kprud\PycharmProjects\Project\users\views.py changed, reloading.
DEBUG:asyncio:Using proactor: IocpProactor
ERROR:django.request:Internal Server Error: /profile/
Traceback (most recent call last):
  File "C:\Users\kprud\anaconda3\lib\site-packages\django\core\handlers\exception.py", line 47, in inner
    response = get_response(request)
  File "C:\Users\kprud\anaconda3\lib\site-packages\django\core\handlers\base.py", line 179, in _get_response
    response = wrapped_callback(request, *callback_args, **callback_kwargs)
  File "C:\Users\kprud\anaconda3\lib\site-packages\django\contrib\auth\decorators.py", line 21, in _wrapped_view
    return view_func(request, *args, **kwargs)
  File "C:\Users\kprud\PycharmProjects\Project\users\views.py", line 59, in profile
    d_form=DOBUpdateForm(instance=request.user.dobdetail)
  File "C:\Users\kprud\anaconda3\lib\site-packages\django\utils\functional.py", line 241, in inner
    return func(self._wrapped, *args)
  File "C:\Users\kprud\anaconda3\lib\site-packages\django\db\models\fields\related_descriptors.py", line 421, in __get__
    raise self.RelatedObjectDoesNotExist(
django.contrib.auth.models.User.dobdetail.RelatedObjectDoesNotExist: User has no dobdetail.
INFO:django.utils.autoreload:C:\Users\kprud\PycharmProjects\Project\users\signals.py changed, reloading.
DEBUG:asyncio:Using proactor: IocpProactor
INFO:django.utils.autoreload:C:\Users\kprud\PycharmProjects\Project\users\signals.py changed, reloading.
DEBUG:asyncio:Using proactor: IocpProactor
DEBUG:asyncio:Using proactor: IocpProactor
ERROR:django.request:Internal Server Error: /profile/
Traceback (most recent call last):
  File "C:\Users\kprud\anaconda3\lib\site-packages\django\core\handlers\exception.py", line 47, in inner
    response = get_response(request)
  File "C:\Users\kprud\anaconda3\lib\site-packages\django\core\handlers\base.py", line 179, in _get_response
    response = wrapped_callback(request, *callback_args, **callback_kwargs)
  File "C:\Users\kprud\anaconda3\lib\site-packages\django\contrib\auth\decorators.py", line 21, in _wrapped_view
    return view_func(request, *args, **kwargs)
  File "C:\Users\kprud\PycharmProjects\Project\users\views.py", line 59, in profile
    d_form=DOBUpdateForm(instance=request.user.dobdetail)
  File "C:\Users\kprud\anaconda3\lib\site-packages\django\utils\functional.py", line 241, in inner
    return func(self._wrapped, *args)
  File "C:\Users\kprud\anaconda3\lib\site-packages\django\db\models\fields\related_descriptors.py", line 421, in __get__
    raise self.RelatedObjectDoesNotExist(
django.contrib.auth.models.User.dobdetail.RelatedObjectDoesNotExist: User has no dobdetail.
ERROR:django.request:Internal Server Error: /profile/
Traceback (most recent call last):
  File "C:\Users\kprud\anaconda3\lib\site-packages\django\core\handlers\exception.py", line 47, in inner
    response = get_response(request)
  File "C:\Users\kprud\anaconda3\lib\site-packages\django\core\handlers\base.py", line 179, in _get_response
    response = wrapped_callback(request, *callback_args, **callback_kwargs)
  File "C:\Users\kprud\anaconda3\lib\site-packages\django\contrib\auth\decorators.py", line 21, in _wrapped_view
    return view_func(request, *args, **kwargs)
  File "C:\Users\kprud\PycharmProjects\Project\users\views.py", line 59, in profile
    d_form=DOBUpdateForm(instance=request.user.dobdetail)
  File "C:\Users\kprud\anaconda3\lib\site-packages\django\utils\functional.py", line 241, in inner
    return func(self._wrapped, *args)
  File "C:\Users\kprud\anaconda3\lib\site-packages\django\db\models\fields\related_descriptors.py", line 421, in __get__
    raise self.RelatedObjectDoesNotExist(
django.contrib.auth.models.User.dobdetail.RelatedObjectDoesNotExist: User has no dobdetail.
ERROR:django.request:Internal Server Error: /
Traceback (most recent call last):
  File "C:\Users\kprud\anaconda3\lib\site-packages\django\db\backends\utils.py", line 84, in _execute
    return self.cursor.execute(sql, params)
  File "C:\Users\kprud\anaconda3\lib\site-packages\django\db\backends\sqlite3\base.py", line 413, in execute
    return Database.Cursor.execute(self, query, params)
sqlite3.IntegrityError: NOT NULL constraint failed: users_dobdetail.dob

The above exception was the direct cause of the following exception:

Traceback (most recent call last):
  File "C:\Users\kprud\anaconda3\lib\site-packages\django\core\handlers\exception.py", line 47, in inner
    response = get_response(request)
  File "C:\Users\kprud\anaconda3\lib\site-packages\django\core\handlers\base.py", line 179, in _get_response
    response = wrapped_callback(request, *callback_args, **callback_kwargs)
  File "C:\Users\kprud\anaconda3\lib\site-packages\django\views\generic\base.py", line 70, in view
    return self.dispatch(request, *args, **kwargs)
  File "C:\Users\kprud\anaconda3\lib\site-packages\django\views\generic\base.py", line 98, in dispatch
    return handler(request, *args, **kwargs)
  File "C:\Users\kprud\PycharmProjects\Project\users\views.py", line 35, in post
    form.save()
  File "C:\Users\kprud\anaconda3\lib\site-packages\django\contrib\auth\forms.py", line 138, in save
    user.save()
  File "C:\Users\kprud\anaconda3\lib\site-packages\django\contrib\auth\base_user.py", line 67, in save
    super().save(*args, **kwargs)
  File "C:\Users\kprud\anaconda3\lib\site-packages\django\db\models\base.py", line 753, in save
    self.save_base(using=using, force_insert=force_insert,
  File "C:\Users\kprud\anaconda3\lib\site-packages\django\db\models\base.py", line 801, in save_base
    post_save.send(
  File "C:\Users\kprud\anaconda3\lib\site-packages\django\dispatch\dispatcher.py", line 177, in send
    return [
  File "C:\Users\kprud\anaconda3\lib\site-packages\django\dispatch\dispatcher.py", line 178, in <listcomp>
    (receiver, receiver(signal=self, sender=sender, **named))
  File "C:\Users\kprud\PycharmProjects\Project\users\signals.py", line 23, in create_dobdetail
    DOBDetail.objects.create(user=instance)
  File "C:\Users\kprud\anaconda3\lib\site-packages\django\db\models\manager.py", line 85, in manager_method
    return getattr(self.get_queryset(), name)(*args, **kwargs)
  File "C:\Users\kprud\anaconda3\lib\site-packages\django\db\models\query.py", line 447, in create
    obj.save(force_insert=True, using=self.db)
  File "C:\Users\kprud\anaconda3\lib\site-packages\django\db\models\base.py", line 753, in save
    self.save_base(using=using, force_insert=force_insert,
  File "C:\Users\kprud\anaconda3\lib\site-packages\django\db\models\base.py", line 790, in save_base
    updated = self._save_table(
  File "C:\Users\kprud\anaconda3\lib\site-packages\django\db\models\base.py", line 895, in _save_table
    results = self._do_insert(cls._base_manager, using, fields, returning_fields, raw)
  File "C:\Users\kprud\anaconda3\lib\site-packages\django\db\models\base.py", line 933, in _do_insert
    return manager._insert(
  File "C:\Users\kprud\anaconda3\lib\site-packages\django\db\models\manager.py", line 85, in manager_method
    return getattr(self.get_queryset(), name)(*args, **kwargs)
  File "C:\Users\kprud\anaconda3\lib\site-packages\django\db\models\query.py", line 1254, in _insert
    return query.get_compiler(using=using).execute_sql(returning_fields)
  File "C:\Users\kprud\anaconda3\lib\site-packages\django\db\models\sql\compiler.py", line 1397, in execute_sql
    cursor.execute(sql, params)
  File "C:\Users\kprud\anaconda3\lib\site-packages\django\db\backends\utils.py", line 98, in execute
    return super().execute(sql, params)
  File "C:\Users\kprud\anaconda3\lib\site-packages\django\db\backends\utils.py", line 66, in execute
    return self._execute_with_wrappers(sql, params, many=False, executor=self._execute)
  File "C:\Users\kprud\anaconda3\lib\site-packages\django\db\backends\utils.py", line 75, in _execute_with_wrappers
    return executor(sql, params, many, context)
  File "C:\Users\kprud\anaconda3\lib\site-packages\django\db\backends\utils.py", line 84, in _execute
    return self.cursor.execute(sql, params)
  File "C:\Users\kprud\anaconda3\lib\site-packages\django\db\utils.py", line 90, in __exit__
    raise dj_exc_value.with_traceback(traceback) from exc_value
  File "C:\Users\kprud\anaconda3\lib\site-packages\django\db\backends\utils.py", line 84, in _execute
    return self.cursor.execute(sql, params)
  File "C:\Users\kprud\anaconda3\lib\site-packages\django\db\backends\sqlite3\base.py", line 413, in execute
    return Database.Cursor.execute(self, query, params)
django.db.utils.IntegrityError: NOT NULL constraint failed: users_dobdetail.dob
INFO:django.utils.autoreload:C:\Users\kprud\PycharmProjects\Project\users\models.py changed, reloading.
DEBUG:asyncio:Using proactor: IocpProactor
DEBUG:asyncio:Using proactor: IocpProactor
DEBUG:asyncio:Using proactor: IocpProactor
DEBUG:asyncio:Using proactor: IocpProactor
ERROR:django.request:Internal Server Error: /login/
Traceback (most recent call last):
  File "C:\Users\kprud\anaconda3\lib\site-packages\django\core\handlers\exception.py", line 47, in inner
    response = get_response(request)
  File "C:\Users\kprud\anaconda3\lib\site-packages\django\core\handlers\base.py", line 179, in _get_response
    response = wrapped_callback(request, *callback_args, **callback_kwargs)
  File "C:\Users\kprud\anaconda3\lib\site-packages\django\views\generic\base.py", line 70, in view
    return self.dispatch(request, *args, **kwargs)
  File "C:\Users\kprud\anaconda3\lib\site-packages\django\utils\decorators.py", line 43, in _wrapper
    return bound_method(*args, **kwargs)
  File "C:\Users\kprud\anaconda3\lib\site-packages\django\views\decorators\debug.py", line 89, in sensitive_post_parameters_wrapper
    return view(request, *args, **kwargs)
  File "C:\Users\kprud\anaconda3\lib\site-packages\django\utils\decorators.py", line 43, in _wrapper
    return bound_method(*args, **kwargs)
  File "C:\Users\kprud\anaconda3\lib\site-packages\django\utils\decorators.py", line 130, in _wrapped_view
    response = view_func(request, *args, **kwargs)
  File "C:\Users\kprud\anaconda3\lib\site-packages\django\utils\decorators.py", line 43, in _wrapper
    return bound_method(*args, **kwargs)
  File "C:\Users\kprud\anaconda3\lib\site-packages\django\views\decorators\cache.py", line 44, in _wrapped_view_func
    response = view_func(request, *args, **kwargs)
  File "C:\Users\kprud\anaconda3\lib\site-packages\django\contrib\auth\views.py", line 63, in dispatch
    return super().dispatch(request, *args, **kwargs)
  File "C:\Users\kprud\anaconda3\lib\site-packages\django\views\generic\base.py", line 98, in dispatch
    return handler(request, *args, **kwargs)
  File "C:\Users\kprud\anaconda3\lib\site-packages\django\views\generic\edit.py", line 142, in post
    return self.form_valid(form)
  File "C:\Users\kprud\anaconda3\lib\site-packages\django\contrib\auth\views.py", line 92, in form_valid
    auth_login(self.request, form.get_user())
  File "C:\Users\kprud\anaconda3\lib\site-packages\django\contrib\auth\__init__.py", line 132, in login
    user_logged_in.send(sender=user.__class__, request=request, user=user)
  File "C:\Users\kprud\anaconda3\lib\site-packages\django\dispatch\dispatcher.py", line 177, in send
    return [
  File "C:\Users\kprud\anaconda3\lib\site-packages\django\dispatch\dispatcher.py", line 178, in <listcomp>
    (receiver, receiver(signal=self, sender=sender, **named))
  File "C:\Users\kprud\anaconda3\lib\site-packages\django\contrib\auth\models.py", line 20, in update_last_login
    user.save(update_fields=['last_login'])
  File "C:\Users\kprud\anaconda3\lib\site-packages\django\contrib\auth\base_user.py", line 67, in save
    super().save(*args, **kwargs)
  File "C:\Users\kprud\anaconda3\lib\site-packages\django\db\models\base.py", line 753, in save
    self.save_base(using=using, force_insert=force_insert,
  File "C:\Users\kprud\anaconda3\lib\site-packages\django\db\models\base.py", line 801, in save_base
    post_save.send(
  File "C:\Users\kprud\anaconda3\lib\site-packages\django\dispatch\dispatcher.py", line 177, in send
    return [
  File "C:\Users\kprud\anaconda3\lib\site-packages\django\dispatch\dispatcher.py", line 178, in <listcomp>
    (receiver, receiver(signal=self, sender=sender, **named))
  File "C:\Users\kprud\PycharmProjects\Project\users\signals.py", line 28, in save_dobdetail
    instance.dobdetail.save()
  File "C:\Users\kprud\anaconda3\lib\site-packages\django\db\models\fields\related_descriptors.py", line 421, in __get__
    raise self.RelatedObjectDoesNotExist(
django.contrib.auth.models.User.dobdetail.RelatedObjectDoesNotExist: User has no dobdetail.
ERROR:django.request:Internal Server Error: /login/
Traceback (most recent call last):
  File "C:\Users\kprud\anaconda3\lib\site-packages\django\core\handlers\exception.py", line 47, in inner
    response = get_response(request)
  File "C:\Users\kprud\anaconda3\lib\site-packages\django\core\handlers\base.py", line 179, in _get_response
    response = wrapped_callback(request, *callback_args, **callback_kwargs)
  File "C:\Users\kprud\anaconda3\lib\site-packages\django\views\generic\base.py", line 70, in view
    return self.dispatch(request, *args, **kwargs)
  File "C:\Users\kprud\anaconda3\lib\site-packages\django\utils\decorators.py", line 43, in _wrapper
    return bound_method(*args, **kwargs)
  File "C:\Users\kprud\anaconda3\lib\site-packages\django\views\decorators\debug.py", line 89, in sensitive_post_parameters_wrapper
    return view(request, *args, **kwargs)
  File "C:\Users\kprud\anaconda3\lib\site-packages\django\utils\decorators.py", line 43, in _wrapper
    return bound_method(*args, **kwargs)
  File "C:\Users\kprud\anaconda3\lib\site-packages\django\utils\decorators.py", line 130, in _wrapped_view
    response = view_func(request, *args, **kwargs)
  File "C:\Users\kprud\anaconda3\lib\site-packages\django\utils\decorators.py", line 43, in _wrapper
    return bound_method(*args, **kwargs)
  File "C:\Users\kprud\anaconda3\lib\site-packages\django\views\decorators\cache.py", line 44, in _wrapped_view_func
    response = view_func(request, *args, **kwargs)
  File "C:\Users\kprud\anaconda3\lib\site-packages\django\contrib\auth\views.py", line 63, in dispatch
    return super().dispatch(request, *args, **kwargs)
  File "C:\Users\kprud\anaconda3\lib\site-packages\django\views\generic\base.py", line 98, in dispatch
    return handler(request, *args, **kwargs)
  File "C:\Users\kprud\anaconda3\lib\site-packages\django\views\generic\edit.py", line 142, in post
    return self.form_valid(form)
  File "C:\Users\kprud\anaconda3\lib\site-packages\django\contrib\auth\views.py", line 92, in form_valid
    auth_login(self.request, form.get_user())
  File "C:\Users\kprud\anaconda3\lib\site-packages\django\contrib\auth\__init__.py", line 132, in login
    user_logged_in.send(sender=user.__class__, request=request, user=user)
  File "C:\Users\kprud\anaconda3\lib\site-packages\django\dispatch\dispatcher.py", line 177, in send
    return [
  File "C:\Users\kprud\anaconda3\lib\site-packages\django\dispatch\dispatcher.py", line 178, in <listcomp>
    (receiver, receiver(signal=self, sender=sender, **named))
  File "C:\Users\kprud\anaconda3\lib\site-packages\django\contrib\auth\models.py", line 20, in update_last_login
    user.save(update_fields=['last_login'])
  File "C:\Users\kprud\anaconda3\lib\site-packages\django\contrib\auth\base_user.py", line 67, in save
    super().save(*args, **kwargs)
  File "C:\Users\kprud\anaconda3\lib\site-packages\django\db\models\base.py", line 753, in save
    self.save_base(using=using, force_insert=force_insert,
  File "C:\Users\kprud\anaconda3\lib\site-packages\django\db\models\base.py", line 801, in save_base
    post_save.send(
  File "C:\Users\kprud\anaconda3\lib\site-packages\django\dispatch\dispatcher.py", line 177, in send
    return [
  File "C:\Users\kprud\anaconda3\lib\site-packages\django\dispatch\dispatcher.py", line 178, in <listcomp>
    (receiver, receiver(signal=self, sender=sender, **named))
  File "C:\Users\kprud\PycharmProjects\Project\users\signals.py", line 28, in save_dobdetail
    instance.dobdetail.save()
  File "C:\Users\kprud\anaconda3\lib\site-packages\django\db\models\fields\related_descriptors.py", line 421, in __get__
    raise self.RelatedObjectDoesNotExist(
django.contrib.auth.models.User.dobdetail.RelatedObjectDoesNotExist: User has no dobdetail.
ERROR:django.request:Internal Server Error: /admin/login/
Traceback (most recent call last):
  File "C:\Users\kprud\anaconda3\lib\site-packages\django\core\handlers\exception.py", line 47, in inner
    response = get_response(request)
  File "C:\Users\kprud\anaconda3\lib\site-packages\django\core\handlers\base.py", line 179, in _get_response
    response = wrapped_callback(request, *callback_args, **callback_kwargs)
  File "C:\Users\kprud\anaconda3\lib\site-packages\django\views\decorators\cache.py", line 44, in _wrapped_view_func
    response = view_func(request, *args, **kwargs)
  File "C:\Users\kprud\anaconda3\lib\site-packages\django\contrib\admin\sites.py", line 410, in login
    return LoginView.as_view(**defaults)(request)
  File "C:\Users\kprud\anaconda3\lib\site-packages\django\views\generic\base.py", line 70, in view
    return self.dispatch(request, *args, **kwargs)
  File "C:\Users\kprud\anaconda3\lib\site-packages\django\utils\decorators.py", line 43, in _wrapper
    return bound_method(*args, **kwargs)
  File "C:\Users\kprud\anaconda3\lib\site-packages\django\views\decorators\debug.py", line 89, in sensitive_post_parameters_wrapper
    return view(request, *args, **kwargs)
  File "C:\Users\kprud\anaconda3\lib\site-packages\django\utils\decorators.py", line 43, in _wrapper
    return bound_method(*args, **kwargs)
  File "C:\Users\kprud\anaconda3\lib\site-packages\django\utils\decorators.py", line 130, in _wrapped_view
    response = view_func(request, *args, **kwargs)
  File "C:\Users\kprud\anaconda3\lib\site-packages\django\utils\decorators.py", line 43, in _wrapper
    return bound_method(*args, **kwargs)
  File "C:\Users\kprud\anaconda3\lib\site-packages\django\views\decorators\cache.py", line 44, in _wrapped_view_func
    response = view_func(request, *args, **kwargs)
  File "C:\Users\kprud\anaconda3\lib\site-packages\django\contrib\auth\views.py", line 63, in dispatch
    return super().dispatch(request, *args, **kwargs)
  File "C:\Users\kprud\anaconda3\lib\site-packages\django\views\generic\base.py", line 98, in dispatch
    return handler(request, *args, **kwargs)
  File "C:\Users\kprud\anaconda3\lib\site-packages\django\views\generic\edit.py", line 142, in post
    return self.form_valid(form)
  File "C:\Users\kprud\anaconda3\lib\site-packages\django\contrib\auth\views.py", line 92, in form_valid
    auth_login(self.request, form.get_user())
  File "C:\Users\kprud\anaconda3\lib\site-packages\django\contrib\auth\__init__.py", line 132, in login
    user_logged_in.send(sender=user.__class__, request=request, user=user)
  File "C:\Users\kprud\anaconda3\lib\site-packages\django\dispatch\dispatcher.py", line 177, in send
    return [
  File "C:\Users\kprud\anaconda3\lib\site-packages\django\dispatch\dispatcher.py", line 178, in <listcomp>
    (receiver, receiver(signal=self, sender=sender, **named))
  File "C:\Users\kprud\anaconda3\lib\site-packages\django\contrib\auth\models.py", line 20, in update_last_login
    user.save(update_fields=['last_login'])
  File "C:\Users\kprud\anaconda3\lib\site-packages\django\contrib\auth\base_user.py", line 67, in save
    super().save(*args, **kwargs)
  File "C:\Users\kprud\anaconda3\lib\site-packages\django\db\models\base.py", line 753, in save
    self.save_base(using=using, force_insert=force_insert,
  File "C:\Users\kprud\anaconda3\lib\site-packages\django\db\models\base.py", line 801, in save_base
    post_save.send(
  File "C:\Users\kprud\anaconda3\lib\site-packages\django\dispatch\dispatcher.py", line 177, in send
    return [
  File "C:\Users\kprud\anaconda3\lib\site-packages\django\dispatch\dispatcher.py", line 178, in <listcomp>
    (receiver, receiver(signal=self, sender=sender, **named))
  File "C:\Users\kprud\PycharmProjects\Project\users\signals.py", line 28, in save_dobdetail
    instance.dobdetail.save()
  File "C:\Users\kprud\anaconda3\lib\site-packages\django\db\models\fields\related_descriptors.py", line 421, in __get__
    raise self.RelatedObjectDoesNotExist(
django.contrib.auth.models.User.dobdetail.RelatedObjectDoesNotExist: User has no dobdetail.
DEBUG:asyncio:Using proactor: IocpProactor
ERROR:django.request:Internal Server Error: /login/
Traceback (most recent call last):
  File "C:\Users\kprud\anaconda3\lib\site-packages\django\core\handlers\exception.py", line 47, in inner
    response = get_response(request)
  File "C:\Users\kprud\anaconda3\lib\site-packages\django\core\handlers\base.py", line 179, in _get_response
    response = wrapped_callback(request, *callback_args, **callback_kwargs)
  File "C:\Users\kprud\anaconda3\lib\site-packages\django\views\generic\base.py", line 70, in view
    return self.dispatch(request, *args, **kwargs)
  File "C:\Users\kprud\anaconda3\lib\site-packages\django\utils\decorators.py", line 43, in _wrapper
    return bound_method(*args, **kwargs)
  File "C:\Users\kprud\anaconda3\lib\site-packages\django\views\decorators\debug.py", line 89, in sensitive_post_parameters_wrapper
    return view(request, *args, **kwargs)
  File "C:\Users\kprud\anaconda3\lib\site-packages\django\utils\decorators.py", line 43, in _wrapper
    return bound_method(*args, **kwargs)
  File "C:\Users\kprud\anaconda3\lib\site-packages\django\utils\decorators.py", line 130, in _wrapped_view
    response = view_func(request, *args, **kwargs)
  File "C:\Users\kprud\anaconda3\lib\site-packages\django\utils\decorators.py", line 43, in _wrapper
    return bound_method(*args, **kwargs)
  File "C:\Users\kprud\anaconda3\lib\site-packages\django\views\decorators\cache.py", line 44, in _wrapped_view_func
    response = view_func(request, *args, **kwargs)
  File "C:\Users\kprud\anaconda3\lib\site-packages\django\contrib\auth\views.py", line 63, in dispatch
    return super().dispatch(request, *args, **kwargs)
  File "C:\Users\kprud\anaconda3\lib\site-packages\django\views\generic\base.py", line 98, in dispatch
    return handler(request, *args, **kwargs)
  File "C:\Users\kprud\anaconda3\lib\site-packages\django\views\generic\edit.py", line 142, in post
    return self.form_valid(form)
  File "C:\Users\kprud\anaconda3\lib\site-packages\django\contrib\auth\views.py", line 92, in form_valid
    auth_login(self.request, form.get_user())
  File "C:\Users\kprud\anaconda3\lib\site-packages\django\contrib\auth\__init__.py", line 132, in login
    user_logged_in.send(sender=user.__class__, request=request, user=user)
  File "C:\Users\kprud\anaconda3\lib\site-packages\django\dispatch\dispatcher.py", line 177, in send
    return [
  File "C:\Users\kprud\anaconda3\lib\site-packages\django\dispatch\dispatcher.py", line 178, in <listcomp>
    (receiver, receiver(signal=self, sender=sender, **named))
  File "C:\Users\kprud\anaconda3\lib\site-packages\django\contrib\auth\models.py", line 20, in update_last_login
    user.save(update_fields=['last_login'])
  File "C:\Users\kprud\anaconda3\lib\site-packages\django\contrib\auth\base_user.py", line 67, in save
    super().save(*args, **kwargs)
  File "C:\Users\kprud\anaconda3\lib\site-packages\django\db\models\base.py", line 753, in save
    self.save_base(using=using, force_insert=force_insert,
  File "C:\Users\kprud\anaconda3\lib\site-packages\django\db\models\base.py", line 801, in save_base
    post_save.send(
  File "C:\Users\kprud\anaconda3\lib\site-packages\django\dispatch\dispatcher.py", line 177, in send
    return [
  File "C:\Users\kprud\anaconda3\lib\site-packages\django\dispatch\dispatcher.py", line 178, in <listcomp>
    (receiver, receiver(signal=self, sender=sender, **named))
  File "C:\Users\kprud\PycharmProjects\Project\users\signals.py", line 28, in save_dobdetail
    instance.dobdetail.save()
  File "C:\Users\kprud\anaconda3\lib\site-packages\django\db\models\fields\related_descriptors.py", line 421, in __get__
    raise self.RelatedObjectDoesNotExist(
django.contrib.auth.models.User.dobdetail.RelatedObjectDoesNotExist: User has no dobdetail.
WARNING:django.request:Not Found: /media/https:/source.unsplash.com/random/300x200?sig=${Math.random()}
WARNING:django.request:Not Found: /media/https:/source.unsplash.com/random/300x200?sig=${Math.random()}
ERROR:django.request:Internal Server Error: /login/
Traceback (most recent call last):
  File "C:\Users\kprud\anaconda3\lib\site-packages\django\core\handlers\exception.py", line 47, in inner
    response = get_response(request)
  File "C:\Users\kprud\anaconda3\lib\site-packages\django\core\handlers\base.py", line 179, in _get_response
    response = wrapped_callback(request, *callback_args, **callback_kwargs)
  File "C:\Users\kprud\anaconda3\lib\site-packages\django\views\generic\base.py", line 70, in view
    return self.dispatch(request, *args, **kwargs)
  File "C:\Users\kprud\anaconda3\lib\site-packages\django\utils\decorators.py", line 43, in _wrapper
    return bound_method(*args, **kwargs)
  File "C:\Users\kprud\anaconda3\lib\site-packages\django\views\decorators\debug.py", line 89, in sensitive_post_parameters_wrapper
    return view(request, *args, **kwargs)
  File "C:\Users\kprud\anaconda3\lib\site-packages\django\utils\decorators.py", line 43, in _wrapper
    return bound_method(*args, **kwargs)
  File "C:\Users\kprud\anaconda3\lib\site-packages\django\utils\decorators.py", line 130, in _wrapped_view
    response = view_func(request, *args, **kwargs)
  File "C:\Users\kprud\anaconda3\lib\site-packages\django\utils\decorators.py", line 43, in _wrapper
    return bound_method(*args, **kwargs)
  File "C:\Users\kprud\anaconda3\lib\site-packages\django\views\decorators\cache.py", line 44, in _wrapped_view_func
    response = view_func(request, *args, **kwargs)
  File "C:\Users\kprud\anaconda3\lib\site-packages\django\contrib\auth\views.py", line 63, in dispatch
    return super().dispatch(request, *args, **kwargs)
  File "C:\Users\kprud\anaconda3\lib\site-packages\django\views\generic\base.py", line 98, in dispatch
    return handler(request, *args, **kwargs)
  File "C:\Users\kprud\anaconda3\lib\site-packages\django\views\generic\edit.py", line 142, in post
    return self.form_valid(form)
  File "C:\Users\kprud\anaconda3\lib\site-packages\django\contrib\auth\views.py", line 92, in form_valid
    auth_login(self.request, form.get_user())
  File "C:\Users\kprud\anaconda3\lib\site-packages\django\contrib\auth\__init__.py", line 132, in login
    user_logged_in.send(sender=user.__class__, request=request, user=user)
  File "C:\Users\kprud\anaconda3\lib\site-packages\django\dispatch\dispatcher.py", line 177, in send
    return [
  File "C:\Users\kprud\anaconda3\lib\site-packages\django\dispatch\dispatcher.py", line 178, in <listcomp>
    (receiver, receiver(signal=self, sender=sender, **named))
  File "C:\Users\kprud\anaconda3\lib\site-packages\django\contrib\auth\models.py", line 20, in update_last_login
    user.save(update_fields=['last_login'])
  File "C:\Users\kprud\anaconda3\lib\site-packages\django\contrib\auth\base_user.py", line 67, in save
    super().save(*args, **kwargs)
  File "C:\Users\kprud\anaconda3\lib\site-packages\django\db\models\base.py", line 753, in save
    self.save_base(using=using, force_insert=force_insert,
  File "C:\Users\kprud\anaconda3\lib\site-packages\django\db\models\base.py", line 801, in save_base
    post_save.send(
  File "C:\Users\kprud\anaconda3\lib\site-packages\django\dispatch\dispatcher.py", line 177, in send
    return [
  File "C:\Users\kprud\anaconda3\lib\site-packages\django\dispatch\dispatcher.py", line 178, in <listcomp>
    (receiver, receiver(signal=self, sender=sender, **named))
  File "C:\Users\kprud\PycharmProjects\Project\users\signals.py", line 28, in save_dobdetail
    instance.dobdetail.save()
  File "C:\Users\kprud\anaconda3\lib\site-packages\django\db\models\fields\related_descriptors.py", line 421, in __get__
    raise self.RelatedObjectDoesNotExist(
django.contrib.auth.models.User.dobdetail.RelatedObjectDoesNotExist: User has no dobdetail.
ERROR:django.request:Internal Server Error: /
Traceback (most recent call last):
  File "C:\Users\kprud\anaconda3\lib\site-packages\django\db\backends\utils.py", line 84, in _execute
    return self.cursor.execute(sql, params)
  File "C:\Users\kprud\anaconda3\lib\site-packages\django\db\backends\sqlite3\base.py", line 413, in execute
    return Database.Cursor.execute(self, query, params)
sqlite3.IntegrityError: NOT NULL constraint failed: users_dobdetail.dob

The above exception was the direct cause of the following exception:

Traceback (most recent call last):
  File "C:\Users\kprud\anaconda3\lib\site-packages\django\core\handlers\exception.py", line 47, in inner
    response = get_response(request)
  File "C:\Users\kprud\anaconda3\lib\site-packages\django\core\handlers\base.py", line 179, in _get_response
    response = wrapped_callback(request, *callback_args, **callback_kwargs)
  File "C:\Users\kprud\anaconda3\lib\site-packages\django\views\generic\base.py", line 70, in view
    return self.dispatch(request, *args, **kwargs)
  File "C:\Users\kprud\anaconda3\lib\site-packages\django\views\generic\base.py", line 98, in dispatch
    return handler(request, *args, **kwargs)
  File "C:\Users\kprud\PycharmProjects\Project\users\views.py", line 35, in post
    form.save()
  File "C:\Users\kprud\anaconda3\lib\site-packages\django\contrib\auth\forms.py", line 138, in save
    user.save()
  File "C:\Users\kprud\anaconda3\lib\site-packages\django\contrib\auth\base_user.py", line 67, in save
    super().save(*args, **kwargs)
  File "C:\Users\kprud\anaconda3\lib\site-packages\django\db\models\base.py", line 753, in save
    self.save_base(using=using, force_insert=force_insert,
  File "C:\Users\kprud\anaconda3\lib\site-packages\django\db\models\base.py", line 801, in save_base
    post_save.send(
  File "C:\Users\kprud\anaconda3\lib\site-packages\django\dispatch\dispatcher.py", line 177, in send
    return [
  File "C:\Users\kprud\anaconda3\lib\site-packages\django\dispatch\dispatcher.py", line 178, in <listcomp>
    (receiver, receiver(signal=self, sender=sender, **named))
  File "C:\Users\kprud\PycharmProjects\Project\users\signals.py", line 23, in create_dobdetail
    DOBDetail.objects.create(user=instance)
  File "C:\Users\kprud\anaconda3\lib\site-packages\django\db\models\manager.py", line 85, in manager_method
    return getattr(self.get_queryset(), name)(*args, **kwargs)
  File "C:\Users\kprud\anaconda3\lib\site-packages\django\db\models\query.py", line 447, in create
    obj.save(force_insert=True, using=self.db)
  File "C:\Users\kprud\anaconda3\lib\site-packages\django\db\models\base.py", line 753, in save
    self.save_base(using=using, force_insert=force_insert,
  File "C:\Users\kprud\anaconda3\lib\site-packages\django\db\models\base.py", line 790, in save_base
    updated = self._save_table(
  File "C:\Users\kprud\anaconda3\lib\site-packages\django\db\models\base.py", line 895, in _save_table
    results = self._do_insert(cls._base_manager, using, fields, returning_fields, raw)
  File "C:\Users\kprud\anaconda3\lib\site-packages\django\db\models\base.py", line 933, in _do_insert
    return manager._insert(
  File "C:\Users\kprud\anaconda3\lib\site-packages\django\db\models\manager.py", line 85, in manager_method
    return getattr(self.get_queryset(), name)(*args, **kwargs)
  File "C:\Users\kprud\anaconda3\lib\site-packages\django\db\models\query.py", line 1254, in _insert
    return query.get_compiler(using=using).execute_sql(returning_fields)
  File "C:\Users\kprud\anaconda3\lib\site-packages\django\db\models\sql\compiler.py", line 1397, in execute_sql
    cursor.execute(sql, params)
  File "C:\Users\kprud\anaconda3\lib\site-packages\django\db\backends\utils.py", line 98, in execute
    return super().execute(sql, params)
  File "C:\Users\kprud\anaconda3\lib\site-packages\django\db\backends\utils.py", line 66, in execute
    return self._execute_with_wrappers(sql, params, many=False, executor=self._execute)
  File "C:\Users\kprud\anaconda3\lib\site-packages\django\db\backends\utils.py", line 75, in _execute_with_wrappers
    return executor(sql, params, many, context)
  File "C:\Users\kprud\anaconda3\lib\site-packages\django\db\backends\utils.py", line 84, in _execute
    return self.cursor.execute(sql, params)
  File "C:\Users\kprud\anaconda3\lib\site-packages\django\db\utils.py", line 90, in __exit__
    raise dj_exc_value.with_traceback(traceback) from exc_value
  File "C:\Users\kprud\anaconda3\lib\site-packages\django\db\backends\utils.py", line 84, in _execute
    return self.cursor.execute(sql, params)
  File "C:\Users\kprud\anaconda3\lib\site-packages\django\db\backends\sqlite3\base.py", line 413, in execute
    return Database.Cursor.execute(self, query, params)
django.db.utils.IntegrityError: NOT NULL constraint failed: users_dobdetail.dob
INFO:django.utils.autoreload:C:\Users\kprud\PycharmProjects\Project\users\views.py changed, reloading.
DEBUG:asyncio:Using proactor: IocpProactor
DEBUG:asyncio:Using proactor: IocpProactor
DEBUG:asyncio:Using proactor: IocpProactor
DEBUG:asyncio:Using proactor: IocpProactor
INFO:django.utils.autoreload:C:\Users\kprud\PycharmProjects\Project\users\models.py changed, reloading.
DEBUG:asyncio:Using proactor: IocpProactor
DEBUG:asyncio:Using proactor: IocpProactor
DEBUG:asyncio:Using proactor: IocpProactor
DEBUG:asyncio:Using proactor: IocpProactor
DEBUG:asyncio:Using proactor: IocpProactor
DEBUG:asyncio:Using proactor: IocpProactor
DEBUG:asyncio:Using proactor: IocpProactor
DEBUG:asyncio:Using proactor: IocpProactor
DEBUG:asyncio:Using proactor: IocpProactor
DEBUG:asyncio:Using proactor: IocpProactor
INFO:django.utils.autoreload:C:\Users\kprud\PycharmProjects\Project\users\migrations\0001_initial.py changed, reloading.
DEBUG:asyncio:Using proactor: IocpProactor
DEBUG:asyncio:Using proactor: IocpProactor
DEBUG:asyncio:Using proactor: IocpProactor
INFO:django.utils.autoreload:C:\Users\kprud\PycharmProjects\Project\users\models.py changed, reloading.
DEBUG:asyncio:Using proactor: IocpProactor
DEBUG:asyncio:Using proactor: IocpProactor
INFO:django.utils.autoreload:C:\Users\kprud\PycharmProjects\Project\users\migrations\0001_initial.py changed, reloading.
DEBUG:asyncio:Using proactor: IocpProactor
DEBUG:asyncio:Using proactor: IocpProactor
DEBUG:asyncio:Using proactor: IocpProactor
DEBUG:PIL.Image:Importing BlpImagePlugin
DEBUG:PIL.Image:Importing BmpImagePlugin
DEBUG:PIL.Image:Importing BufrStubImagePlugin
DEBUG:PIL.Image:Importing CurImagePlugin
DEBUG:PIL.Image:Importing DcxImagePlugin
DEBUG:PIL.Image:Importing DdsImagePlugin
DEBUG:PIL.Image:Importing EpsImagePlugin
DEBUG:PIL.Image:Importing FitsStubImagePlugin
DEBUG:PIL.Image:Importing FliImagePlugin
DEBUG:PIL.Image:Importing FpxImagePlugin
DEBUG:PIL.Image:Importing FtexImagePlugin
DEBUG:PIL.Image:Importing GbrImagePlugin
DEBUG:PIL.Image:Importing GifImagePlugin
DEBUG:PIL.Image:Importing GribStubImagePlugin
DEBUG:PIL.Image:Importing Hdf5StubImagePlugin
DEBUG:PIL.Image:Importing IcnsImagePlugin
DEBUG:PIL.Image:Importing IcoImagePlugin
DEBUG:PIL.Image:Importing ImImagePlugin
DEBUG:PIL.Image:Importing ImtImagePlugin
DEBUG:PIL.Image:Importing IptcImagePlugin
DEBUG:PIL.Image:Importing JpegImagePlugin
DEBUG:PIL.Image:Importing Jpeg2KImagePlugin
DEBUG:PIL.Image:Importing McIdasImagePlugin
DEBUG:PIL.Image:Importing MicImagePlugin
DEBUG:PIL.Image:Importing MpegImagePlugin
DEBUG:PIL.Image:Importing MpoImagePlugin
DEBUG:PIL.Image:Importing MspImagePlugin
DEBUG:PIL.Image:Importing PalmImagePlugin
DEBUG:PIL.Image:Importing PcdImagePlugin
DEBUG:PIL.Image:Importing PcxImagePlugin
DEBUG:PIL.Image:Importing PdfImagePlugin
DEBUG:PIL.Image:Importing PixarImagePlugin
DEBUG:PIL.Image:Importing PngImagePlugin
DEBUG:PIL.Image:Importing PpmImagePlugin
DEBUG:PIL.Image:Importing PsdImagePlugin
DEBUG:PIL.Image:Importing SgiImagePlugin
DEBUG:PIL.Image:Importing SpiderImagePlugin
DEBUG:PIL.Image:Importing SunImagePlugin
DEBUG:PIL.Image:Importing TgaImagePlugin
DEBUG:PIL.Image:Importing TiffImagePlugin
DEBUG:PIL.Image:Importing WebPImagePlugin
DEBUG:PIL.Image:Importing WmfImagePlugin
DEBUG:PIL.Image:Importing XbmImagePlugin
DEBUG:PIL.Image:Importing XpmImagePlugin
DEBUG:PIL.Image:Importing XVThumbImagePlugin
DEBUG:urllib3.connectionpool:Starting new HTTPS connection (1): zenquotes.io:443
DEBUG:urllib3.connectionpool:https://zenquotes.io:443 "GET /api/random HTTP/1.1" 200 None
DEBUG:root:prudhvi
DEBUG:root:k.prudhvireddy1996@gmail.com
INFO:django.utils.autoreload:C:\Users\kprud\PycharmProjects\Project\users\forms.py changed, reloading.
DEBUG:asyncio:Using proactor: IocpProactor
INFO:django.utils.autoreload:C:\Users\kprud\PycharmProjects\Project\users\views.py changed, reloading.
DEBUG:asyncio:Using proactor: IocpProactor
DEBUG:PIL.Image:Importing BlpImagePlugin
DEBUG:PIL.Image:Importing BmpImagePlugin
DEBUG:PIL.Image:Importing BufrStubImagePlugin
DEBUG:PIL.Image:Importing CurImagePlugin
DEBUG:PIL.Image:Importing DcxImagePlugin
DEBUG:PIL.Image:Importing DdsImagePlugin
DEBUG:PIL.Image:Importing EpsImagePlugin
DEBUG:PIL.Image:Importing FitsStubImagePlugin
DEBUG:PIL.Image:Importing FliImagePlugin
DEBUG:PIL.Image:Importing FpxImagePlugin
DEBUG:PIL.Image:Importing FtexImagePlugin
DEBUG:PIL.Image:Importing GbrImagePlugin
DEBUG:PIL.Image:Importing GifImagePlugin
DEBUG:PIL.Image:Importing GribStubImagePlugin
DEBUG:PIL.Image:Importing Hdf5StubImagePlugin
DEBUG:PIL.Image:Importing IcnsImagePlugin
DEBUG:PIL.Image:Importing IcoImagePlugin
DEBUG:PIL.Image:Importing ImImagePlugin
DEBUG:PIL.Image:Importing ImtImagePlugin
DEBUG:PIL.Image:Importing IptcImagePlugin
DEBUG:PIL.Image:Importing JpegImagePlugin
DEBUG:PIL.Image:Importing Jpeg2KImagePlugin
DEBUG:PIL.Image:Importing McIdasImagePlugin
DEBUG:PIL.Image:Importing MicImagePlugin
DEBUG:PIL.Image:Importing MpegImagePlugin
DEBUG:PIL.Image:Importing MpoImagePlugin
DEBUG:PIL.Image:Importing MspImagePlugin
DEBUG:PIL.Image:Importing PalmImagePlugin
DEBUG:PIL.Image:Importing PcdImagePlugin
DEBUG:PIL.Image:Importing PcxImagePlugin
DEBUG:PIL.Image:Importing PdfImagePlugin
DEBUG:PIL.Image:Importing PixarImagePlugin
DEBUG:PIL.Image:Importing PngImagePlugin
DEBUG:PIL.Image:Importing PpmImagePlugin
DEBUG:PIL.Image:Importing PsdImagePlugin
DEBUG:PIL.Image:Importing SgiImagePlugin
DEBUG:PIL.Image:Importing SpiderImagePlugin
DEBUG:PIL.Image:Importing SunImagePlugin
DEBUG:PIL.Image:Importing TgaImagePlugin
DEBUG:PIL.Image:Importing TiffImagePlugin
DEBUG:PIL.Image:Importing WebPImagePlugin
DEBUG:PIL.Image:Importing WmfImagePlugin
DEBUG:PIL.Image:Importing XbmImagePlugin
DEBUG:PIL.Image:Importing XpmImagePlugin
DEBUG:PIL.Image:Importing XVThumbImagePlugin
DEBUG:urllib3.connectionpool:Starting new HTTPS connection (1): zenquotes.io:443
DEBUG:urllib3.connectionpool:https://zenquotes.io:443 "GET /api/random HTTP/1.1" 200 None
DEBUG:root:reddy
DEBUG:root:k.prudhvireddy1996@gmail.com
DEBUG:PIL.TiffImagePlugin:tag: Orientation (274) - type: short (3) - value: b'\x00\x01'
DEBUG:PIL.TiffImagePlugin:tag: XResolution (282) - type: rational (5) Tag Location: 34 - Data Location: 98 - value: b"\x00\n\xfc\x80\x00\x00'\x10"
DEBUG:PIL.TiffImagePlugin:tag: YResolution (283) - type: rational (5) Tag Location: 46 - Data Location: 106 - value: b"\x00\n\xfc\x80\x00\x00'\x10"
DEBUG:PIL.TiffImagePlugin:tag: ResolutionUnit (296) - type: short (3) - value: b'\x00\x02'
DEBUG:PIL.TiffImagePlugin:tag: Software (305) - type: string (2) Tag Location: 70 - Data Location: 114 - value: <table: 33 bytes>
DEBUG:PIL.TiffImagePlugin:tag: DateTime (306) - type: string (2) Tag Location: 82 - Data Location: 147 - value: b'2020:10:04 23:38:23\x00'
DEBUG:PIL.TiffImagePlugin:tag: ExifIFD (34665) - type: long (4) - value: b'\x00\x00\x00\xa8'
DEBUG:PIL.TiffImagePlugin:tag: Orientation (274) - type: short (3) - value: b'\x00\x01'
DEBUG:PIL.TiffImagePlugin:tag: XResolution (282) - type: rational (5) Tag Location: 34 - Data Location: 98 - value: b"\x00\n\xfc\x80\x00\x00'\x10"
DEBUG:PIL.TiffImagePlugin:tag: YResolution (283) - type: rational (5) Tag Location: 46 - Data Location: 106 - value: b"\x00\n\xfc\x80\x00\x00'\x10"
DEBUG:PIL.TiffImagePlugin:tag: ResolutionUnit (296) - type: short (3) - value: b'\x00\x02'
DEBUG:PIL.TiffImagePlugin:tag: Software (305) - type: string (2) Tag Location: 70 - Data Location: 114 - value: <table: 33 bytes>
DEBUG:PIL.TiffImagePlugin:tag: DateTime (306) - type: string (2) Tag Location: 82 - Data Location: 147 - value: b'2020:10:04 23:38:23\x00'
DEBUG:PIL.TiffImagePlugin:tag: ExifIFD (34665) - type: long (4) - value: b'\x00\x00\x00\xa8'
DEBUG:asyncio:Using proactor: IocpProactor
